Workbook

Sheet Große + Kleine Hausnummer
A1: Große und Kleine Hausnummer
A2: Name | B2: Große Hausnummer | E2: Platz | F2: Kleine Hausnummer | I2: Platz
A3: Michael | E3: =IF(OR(B3="",C3="",D3="")=1,"",_xlfn.RANK.EQ(RECHNEN!A1,RECHNEN!$A$1:$A$15,0)) -> 1 | I3: =IF(OR(F3="",G3="",H3="")=1,"",RECHNEN!$L$34+1-_xlfn.RANK.EQ(RECHNEN!B1,RECHNEN!$B$1:$B$16,0)) -> 11
A4: Hilde | E4: =IF(OR(B4="",C4="",D4="")=1,"",_xlfn.RANK.EQ(RECHNEN!A2,RECHNEN!$A$1:$A$15,0)) -> 1 | I4: =IF(OR(F4="",G4="",H4="")=1,"",RECHNEN!$L$34+1-_xlfn.RANK.EQ(RECHNEN!B2,RECHNEN!$B$1:$B$16,0)) -> 11
A5: Peter | E5: =IF(OR(B5="",C5="",D5="")=1,"",_xlfn.RANK.EQ(RECHNEN!A3,RECHNEN!$A$1:$A$15,0)) -> 1 | I5: =IF(OR(F5="",G5="",H5="")=1,"",RECHNEN!$L$34+1-_xlfn.RANK.EQ(RECHNEN!B3,RECHNEN!$B$1:$B$16,0)) -> 11
A6: Brigitte | E6: =IF(OR(B6="",C6="",D6="")=1,"",_xlfn.RANK.EQ(RECHNEN!A4,RECHNEN!$A$1:$A$15,0)) -> 1 | I6: =IF(OR(F6="",G6="",H6="")=1,"",RECHNEN!$L$34+1-_xlfn.RANK.EQ(RECHNEN!B4,RECHNEN!$B$1:$B$16,0)) -> 11
A7: Elke | E7: =IF(OR(B7="",C7="",D7="")=1,"",_xlfn.RANK.EQ(RECHNEN!A5,RECHNEN!$A$1:$A$15,0)) -> 1 | I7: =IF(OR(F7="",G7="",H7="")=1,"",RECHNEN!$L$34+1-_xlfn.RANK.EQ(RECHNEN!B5,RECHNEN!$B$1:$B$16,0)) -> 11
A8: Gerhard | E8: =IF(OR(B8="",C8="",D8="")=1,"",_xlfn.RANK.EQ(RECHNEN!A6,RECHNEN!$A$1:$A$15,0)) -> 1 | I8: =IF(OR(F8="",G8="",H8="")=1,"",RECHNEN!$L$34+1-_xlfn.RANK.EQ(RECHNEN!B6,RECHNEN!$B$1:$B$16,0)) -> 11
A9: Helga | E9: =IF(OR(B9="",C9="",D9="")=1,"",_xlfn.RANK.EQ(RECHNEN!A7,RECHNEN!$A$1:$A$15,0)) -> 1 | I9: =IF(OR(F9="",G9="",H9="")=1,"",RECHNEN!$L$34+1-_xlfn.RANK.EQ(RECHNEN!B7,RECHNEN!$B$1:$B$16,0)) -> 11
A10: Birgit | E10: =IF(OR(B10="",C10="",D10="")=1,"",_xlfn.RANK.EQ(RECHNEN!A8,RECHNEN!$A$1:$A$15,0)) -> 1 | I10: =IF(OR(F10="",G10="",H10="")=1,"",RECHNEN!$L$34+1-_xlfn.RANK.EQ(RECHNEN!B8,RECHNEN!$B$1:$B$16,0)) -> 11
A11: Jo | E11: =IF(OR(B11="",C11="",D11="")=1,"",_xlfn.RANK.EQ(RECHNEN!A9,RECHNEN!$A$1:$A$15,0)) -> 1 | I11: =IF(OR(F11="",G11="",H11="")=1,"",RECHNEN!$L$34+1-_xlfn.RANK.EQ(RECHNEN!B9,RECHNEN!$B$1:$B$16,0)) -> 11
A12: Svenja | E12: =IF(OR(B12="",C12="",D12="")=1,"",_xlfn.RANK.EQ(RECHNEN!A10,RECHNEN!$A$1:$A$15,0)) -> 1 | I12: =IF(OR(F12="",G12="",H12="")=1,"",RECHNEN!$L$34+1-_xlfn.RANK.EQ(RECHNEN!B10,RECHNEN!$B$1:$B$16,0)) -> 11
A13: Marius | E13: =IF(OR(B13="",C13="",D13="")=1,"",_xlfn.RANK.EQ(RECHNEN!A11,RECHNEN!$A$1:$A$15,0)) -> 1 | I13: =IF(OR(F13="",G13="",H13="")=1,"",RECHNEN!$L$34+1-_xlfn.RANK.EQ(RECHNEN!B11,RECHNEN!$B$1:$B$16,0)) -> 11
E14: =IF(OR(B14="",C14="",D14="")=1,"",_xlfn.RANK.EQ(RECHNEN!A12,RECHNEN!$A$1:$A$15,0)) -> 1 | I14: =IF(OR(F14="",G14="",H14="")=1,"",RECHNEN!$L$34+1-_xlfn.RANK.EQ(RECHNEN!B12,RECHNEN!$B$1:$B$16,0)) -> 11
E15: =IF(OR(B15="",C15="",D15="")=1,"",_xlfn.RANK.EQ(RECHNEN!A13,RECHNEN!$A$1:$A$15,0)) -> 1 | I15: =IF(OR(F15="",G15="",H15="")=1,"",RECHNEN!$L$34+1-_xlfn.RANK.EQ(RECHNEN!B13,RECHNEN!$B$1:$B$16,0)) -> 11
E16: =IF(OR(B16="",C16="",D16="")=1,"",_xlfn.RANK.EQ(RECHNEN!A14,RECHNEN!$A$1:$A$15,0)) -> 1 | I16: =IF(OR(F16="",G16="",H16="")=1,"",RECHNEN!$L$34+1-_xlfn.RANK.EQ(RECHNEN!B14,RECHNEN!$B$1:$B$16,0)) -> 11
E17: =IF(OR(B17="",C17="",D17="")=1,"",_xlfn.RANK.EQ(RECHNEN!A15,RECHNEN!$A$1:$A$15,0)) -> 1 | I17: =IF(OR(F17="",G17="",H17="")=1,"",RECHNEN!$L$34+1-_xlfn.RANK.EQ(RECHNEN!B15,RECHNEN!$B$1:$B$16,0)) -> 11

Sheet 17 und 4
A1: 17 und 4 | I1: Ergebnis | J1: Karte | K1: Gesamtergebnis | L1: Platzierung
A2: Michael | I2: =SUM(B2,C2,D2,E2,F2,G2,H2) -> 0 | K2: =SUM(I2,J2) -> 0 | L2: =IF(AND(K2=0,J2=0),"",IF(K2>21,"TOT",IF(K2=21,"1",IF(ABS(K2-21)=SMALL(RECHNEN!$C$1:$C$16,1),"1",IF(ABS(K2-21)=SMALL(RECHNEN!$C$1:$C$16,2),"2",IF(ABS(K2-21)=SMALL(RECHNEN!$C$1:$C$16,3),"3",IF(ABS(K2-21)=SMALL(RECHNEN!$C$1:$C$16,4),"4",IF(ABS(K2-21)=SMALL(RECHNEN!$C$1:$C$16,5),"5",IF(ABS(K2-21)=SMALL(RECHNEN!$C$1:$C$16,6),"6",IF(ABS(K2-21)=SMALL(RECHNEN!$C$1:$C$16,7),"7",IF(ABS(K2-21)=SMALL(RECHNEN!$C$1:$C$16,8),"8",IF(ABS(K2-21)=SMALL(RECHNEN!$C$1:$C$16,9),"9",IF(ABS(K2-21)=SMALL(RECHNEN!$C$1:$C$16,10),"10",IF(ABS(K2-21)=SMALL(RECHNEN!$C$1:$C$16,11),"11",IF(ABS(K2-21)=SMALL(RECHNEN!$C$1:$C$16,12),"12","13")))))))))))))))
A3: Hilde | I3: =SUM(B3,C3,D3,E3,F3,G3,H3) -> 0 | K3: =SUM(I3,J3) -> 0 | L3: =IF(AND(K3=0,J3=0),"",IF(K3>21,"TOT",IF(K3=21,"1",IF(ABS(K3-21)=SMALL(RECHNEN!$C$1:$C$16,1),"1",IF(ABS(K3-21)=SMALL(RECHNEN!$C$1:$C$16,2),"2",IF(ABS(K3-21)=SMALL(RECHNEN!$C$1:$C$16,3),"3",IF(ABS(K3-21)=SMALL(RECHNEN!$C$1:$C$16,4),"4",IF(ABS(K3-21)=SMALL(RECHNEN!$C$1:$C$16,5),"5",IF(ABS(K3-21)=SMALL(RECHNEN!$C$1:$C$16,6),"6",IF(ABS(K3-21)=SMALL(RECHNEN!$C$1:$C$16,7),"7",IF(ABS(K3-21)=SMALL(RECHNEN!$C$1:$C$16,8),"8",IF(ABS(K3-21)=SMALL(RECHNEN!$C$1:$C$16,9),"9",IF(ABS(K3-21)=SMALL(RECHNEN!$C$1:$C$16,10),"10",IF(ABS(K3-21)=SMALL(RECHNEN!$C$1:$C$16,11),"11",IF(ABS(K3-21)=SMALL(RECHNEN!$C$1:$C$16,12),"12","13")))))))))))))))
A4: Peter | I4: =SUM(B4,C4,D4,E4,F4,G4,H4) -> 0 | K4: =SUM(I4,J4) -> 0 | L4: =IF(AND(K4=0,J4=0),"",IF(K4>21,"TOT",IF(K4=21,"1",IF(ABS(K4-21)=SMALL(RECHNEN!$C$1:$C$16,1),"1",IF(ABS(K4-21)=SMALL(RECHNEN!$C$1:$C$16,2),"2",IF(ABS(K4-21)=SMALL(RECHNEN!$C$1:$C$16,3),"3",IF(ABS(K4-21)=SMALL(RECHNEN!$C$1:$C$16,4),"4",IF(ABS(K4-21)=SMALL(RECHNEN!$C$1:$C$16,5),"5",IF(ABS(K4-21)=SMALL(RECHNEN!$C$1:$C$16,6),"6",IF(ABS(K4-21)=SMALL(RECHNEN!$C$1:$C$16,7),"7",IF(ABS(K4-21)=SMALL(RECHNEN!$C$1:$C$16,8),"8",IF(ABS(K4-21)=SMALL(RECHNEN!$C$1:$C$16,9),"9",IF(ABS(K4-21)=SMALL(RECHNEN!$C$1:$C$16,10),"10",IF(ABS(K4-21)=SMALL(RECHNEN!$C$1:$C$16,11),"11",IF(ABS(K4-21)=SMALL(RECHNEN!$C$1:$C$16,12),"12","13")))))))))))))))
A5: Brigitte | I5: =SUM(B5,C5,D5,E5,F5,G5,H5) -> 0 | K5: =SUM(I5,J5) -> 0 | L5: =IF(AND(K5=0,J5=0),"",IF(K5>21,"TOT",IF(K5=21,"1",IF(ABS(K5-21)=SMALL(RECHNEN!$C$1:$C$16,1),"1",IF(ABS(K5-21)=SMALL(RECHNEN!$C$1:$C$16,2),"2",IF(ABS(K5-21)=SMALL(RECHNEN!$C$1:$C$16,3),"3",IF(ABS(K5-21)=SMALL(RECHNEN!$C$1:$C$16,4),"4",IF(ABS(K5-21)=SMALL(RECHNEN!$C$1:$C$16,5),"5",IF(ABS(K5-21)=SMALL(RECHNEN!$C$1:$C$16,6),"6",IF(ABS(K5-21)=SMALL(RECHNEN!$C$1:$C$16,7),"7",IF(ABS(K5-21)=SMALL(RECHNEN!$C$1:$C$16,8),"8",IF(ABS(K5-21)=SMALL(RECHNEN!$C$1:$C$16,9),"9",IF(ABS(K5-21)=SMALL(RECHNEN!$C$1:$C$16,10),"10",IF(ABS(K5-21)=SMALL(RECHNEN!$C$1:$C$16,11),"11",IF(ABS(K5-21)=SMALL(RECHNEN!$C$1:$C$16,12),"12","13")))))))))))))))
A6: Elke | I6: =SUM(B6,C6,D6,E6,F6,G6,H6) -> 0 | K6: =SUM(I6,J6) -> 0 | L6: =IF(AND(K6=0,J6=0),"",IF(K6>21,"TOT",IF(K6=21,"1",IF(ABS(K6-21)=SMALL(RECHNEN!$C$1:$C$16,1),"1",IF(ABS(K6-21)=SMALL(RECHNEN!$C$1:$C$16,2),"2",IF(ABS(K6-21)=SMALL(RECHNEN!$C$1:$C$16,3),"3",IF(ABS(K6-21)=SMALL(RECHNEN!$C$1:$C$16,4),"4",IF(ABS(K6-21)=SMALL(RECHNEN!$C$1:$C$16,5),"5",IF(ABS(K6-21)=SMALL(RECHNEN!$C$1:$C$16,6),"6",IF(ABS(K6-21)=SMALL(RECHNEN!$C$1:$C$16,7),"7",IF(ABS(K6-21)=SMALL(RECHNEN!$C$1:$C$16,8),"8",IF(ABS(K6-21)=SMALL(RECHNEN!$C$1:$C$16,9),"9",IF(ABS(K6-21)=SMALL(RECHNEN!$C$1:$C$16,10),"10",IF(ABS(K6-21)=SMALL(RECHNEN!$C$1:$C$16,11),"11",IF(ABS(K6-21)=SMALL(RECHNEN!$C$1:$C$16,12),"12","13")))))))))))))))
A7: Gerhard | I7: =SUM(B7,C7,D7,E7,F7,G7,H7) -> 0 | K7: =SUM(I7,J7) -> 0 | L7: =IF(AND(K7=0,J7=0),"",IF(K7>21,"TOT",IF(K7=21,"1",IF(ABS(K7-21)=SMALL(RECHNEN!$C$1:$C$16,1),"1",IF(ABS(K7-21)=SMALL(RECHNEN!$C$1:$C$16,2),"2",IF(ABS(K7-21)=SMALL(RECHNEN!$C$1:$C$16,3),"3",IF(ABS(K7-21)=SMALL(RECHNEN!$C$1:$C$16,4),"4",IF(ABS(K7-21)=SMALL(RECHNEN!$C$1:$C$16,5),"5",IF(ABS(K7-21)=SMALL(RECHNEN!$C$1:$C$16,6),"6",IF(ABS(K7-21)=SMALL(RECHNEN!$C$1:$C$16,7),"7",IF(ABS(K7-21)=SMALL(RECHNEN!$C$1:$C$16,8),"8",IF(ABS(K7-21)=SMALL(RECHNEN!$C$1:$C$16,9),"9",IF(ABS(K7-21)=SMALL(RECHNEN!$C$1:$C$16,10),"10",IF(ABS(K7-21)=SMALL(RECHNEN!$C$1:$C$16,11),"11",IF(ABS(K7-21)=SMALL(RECHNEN!$C$1:$C$16,12),"12","13")))))))))))))))
A8: Helga | I8: =SUM(B8,C8,D8,E8,F8,G8,H8) -> 0 | K8: =SUM(I8,J8) -> 0 | L8: =IF(AND(K8=0,J8=0),"",IF(K8>21,"TOT",IF(K8=21,"1",IF(ABS(K8-21)=SMALL(RECHNEN!$C$1:$C$16,1),"1",IF(ABS(K8-21)=SMALL(RECHNEN!$C$1:$C$16,2),"2",IF(ABS(K8-21)=SMALL(RECHNEN!$C$1:$C$16,3),"3",IF(ABS(K8-21)=SMALL(RECHNEN!$C$1:$C$16,4),"4",IF(ABS(K8-21)=SMALL(RECHNEN!$C$1:$C$16,5),"5",IF(ABS(K8-21)=SMALL(RECHNEN!$C$1:$C$16,6),"6",IF(ABS(K8-21)=SMALL(RECHNEN!$C$1:$C$16,7),"7",IF(ABS(K8-21)=SMALL(RECHNEN!$C$1:$C$16,8),"8",IF(ABS(K8-21)=SMALL(RECHNEN!$C$1:$C$16,9),"9",IF(ABS(K8-21)=SMALL(RECHNEN!$C$1:$C$16,10),"10",IF(ABS(K8-21)=SMALL(RECHNEN!$C$1:$C$16,11),"11",IF(ABS(K8-21)=SMALL(RECHNEN!$C$1:$C$16,12),"12","13")))))))))))))))
A9: Birgit | I9: =SUM(B9,C9,D9,E9,F9,G9,H9) -> 0 | K9: =SUM(I9,J9) -> 0 | L9: =IF(AND(K9=0,J9=0),"",IF(K9>21,"TOT",IF(K9=21,"1",IF(ABS(K9-21)=SMALL(RECHNEN!$C$1:$C$16,1),"1",IF(ABS(K9-21)=SMALL(RECHNEN!$C$1:$C$16,2),"2",IF(ABS(K9-21)=SMALL(RECHNEN!$C$1:$C$16,3),"3",IF(ABS(K9-21)=SMALL(RECHNEN!$C$1:$C$16,4),"4",IF(ABS(K9-21)=SMALL(RECHNEN!$C$1:$C$16,5),"5",IF(ABS(K9-21)=SMALL(RECHNEN!$C$1:$C$16,6),"6",IF(ABS(K9-21)=SMALL(RECHNEN!$C$1:$C$16,7),"7",IF(ABS(K9-21)=SMALL(RECHNEN!$C$1:$C$16,8),"8",IF(ABS(K9-21)=SMALL(RECHNEN!$C$1:$C$16,9),"9",IF(ABS(K9-21)=SMALL(RECHNEN!$C$1:$C$16,10),"10",IF(ABS(K9-21)=SMALL(RECHNEN!$C$1:$C$16,11),"11",IF(ABS(K9-21)=SMALL(RECHNEN!$C$1:$C$16,12),"12","13")))))))))))))))
A10: Jo | I10: =SUM(B10,C10,D10,E10,F10,G10,H10) -> 0 | K10: =SUM(I10,J10) -> 0 | L10: =IF(AND(K10=0,J10=0),"",IF(K10>21,"TOT",IF(K10=21,"1",IF(ABS(K10-21)=SMALL(RECHNEN!$C$1:$C$16,1),"1",IF(ABS(K10-21)=SMALL(RECHNEN!$C$1:$C$16,2),"2",IF(ABS(K10-21)=SMALL(RECHNEN!$C$1:$C$16,3),"3",IF(ABS(K10-21)=SMALL(RECHNEN!$C$1:$C$16,4),"4",IF(ABS(K10-21)=SMALL(RECHNEN!$C$1:$C$16,5),"5",IF(ABS(K10-21)=SMALL(RECHNEN!$C$1:$C$16,6),"6",IF(ABS(K10-21)=SMALL(RECHNEN!$C$1:$C$16,7),"7",IF(ABS(K10-21)=SMALL(RECHNEN!$C$1:$C$16,8),"8",IF(ABS(K10-21)=SMALL(RECHNEN!$C$1:$C$16,9),"9",IF(ABS(K10-21)=SMALL(RECHNEN!$C$1:$C$16,10),"10",IF(ABS(K10-21)=SMALL(RECHNEN!$C$1:$C$16,11),"11",IF(ABS(K10-21)=SMALL(RECHNEN!$C$1:$C$16,12),"12","13")))))))))))))))
A11: Svenja | I11: =SUM(B11,C11,D11,E11,F11,G11,H11) -> 0 | K11: =SUM(I11,J11) -> 0 | L11: =IF(AND(K11=0,J11=0),"",IF(K11>21,"TOT",IF(K11=21,"1",IF(ABS(K11-21)=SMALL(RECHNEN!$C$1:$C$16,1),"1",IF(ABS(K11-21)=SMALL(RECHNEN!$C$1:$C$16,2),"2",IF(ABS(K11-21)=SMALL(RECHNEN!$C$1:$C$16,3),"3",IF(ABS(K11-21)=SMALL(RECHNEN!$C$1:$C$16,4),"4",IF(ABS(K11-21)=SMALL(RECHNEN!$C$1:$C$16,5),"5",IF(ABS(K11-21)=SMALL(RECHNEN!$C$1:$C$16,6),"6",IF(ABS(K11-21)=SMALL(RECHNEN!$C$1:$C$16,7),"7",IF(ABS(K11-21)=SMALL(RECHNEN!$C$1:$C$16,8),"8",IF(ABS(K11-21)=SMALL(RECHNEN!$C$1:$C$16,9),"9",IF(ABS(K11-21)=SMALL(RECHNEN!$C$1:$C$16,10),"10",IF(ABS(K11-21)=SMALL(RECHNEN!$C$1:$C$16,11),"11",IF(ABS(K11-21)=SMALL(RECHNEN!$C$1:$C$16,12),"12","13")))))))))))))))
A12: Marius | I12: =SUM(B12,C12,D12,E12,F12,G12,H12) -> 0 | K12: =SUM(I12,J12) -> 0 | L12: =IF(AND(K12=0,J12=0),"",IF(K12>21,"TOT",IF(K12=21,"1",IF(ABS(K12-21)=SMALL(RECHNEN!$C$1:$C$16,1),"1",IF(ABS(K12-21)=SMALL(RECHNEN!$C$1:$C$16,2),"2",IF(ABS(K12-21)=SMALL(RECHNEN!$C$1:$C$16,3),"3",IF(ABS(K12-21)=SMALL(RECHNEN!$C$1:$C$16,4),"4",IF(ABS(K12-21)=SMALL(RECHNEN!$C$1:$C$16,5),"5",IF(ABS(K12-21)=SMALL(RECHNEN!$C$1:$C$16,6),"6",IF(ABS(K12-21)=SMALL(RECHNEN!$C$1:$C$16,7),"7",IF(ABS(K12-21)=SMALL(RECHNEN!$C$1:$C$16,8),"8",IF(ABS(K12-21)=SMALL(RECHNEN!$C$1:$C$16,9),"9",IF(ABS(K12-21)=SMALL(RECHNEN!$C$1:$C$16,10),"10",IF(ABS(K12-21)=SMALL(RECHNEN!$C$1:$C$16,11),"11",IF(ABS(K12-21)=SMALL(RECHNEN!$C$1:$C$16,12),"12","13")))))))))))))))
I13: =SUM(B13,C13,D13,E13,F13,G13,H13) -> 0 | K13: =SUM(I13,J13) -> 0 | L13: =IF(AND(K13=0,J13=0),"",IF(K13>21,"TOT",IF(K13=21,"1",IF(ABS(K13-21)=SMALL(RECHNEN!$C$1:$C$16,1),"1",IF(ABS(K13-21)=SMALL(RECHNEN!$C$1:$C$16,2),"2",IF(ABS(K13-21)=SMALL(RECHNEN!$C$1:$C$16,3),"3",IF(ABS(K13-21)=SMALL(RECHNEN!$C$1:$C$16,4),"4",IF(ABS(K13-21)=SMALL(RECHNEN!$C$1:$C$16,5),"5",IF(ABS(K13-21)=SMALL(RECHNEN!$C$1:$C$16,6),"6",IF(ABS(K13-21)=SMALL(RECHNEN!$C$1:$C$16,7),"7",IF(ABS(K13-21)=SMALL(RECHNEN!$C$1:$C$16,8),"8",IF(ABS(K13-21)=SMALL(RECHNEN!$C$1:$C$16,9),"9",IF(ABS(K13-21)=SMALL(RECHNEN!$C$1:$C$16,10),"10",IF(ABS(K13-21)=SMALL(RECHNEN!$C$1:$C$16,11),"11",IF(ABS(K13-21)=SMALL(RECHNEN!$C$1:$C$16,12),"12","13")))))))))))))))
I14: =SUM(B14,C14,D14,E14,F14,G14,H14) -> 0 | K14: =SUM(I14,J14) -> 0 | L14: =IF(AND(K14=0,J14=0),"",IF(K14>21,"TOT",IF(K14=21,"1",IF(ABS(K14-21)=SMALL(RECHNEN!$C$1:$C$16,1),"1",IF(ABS(K14-21)=SMALL(RECHNEN!$C$1:$C$16,2),"2",IF(ABS(K14-21)=SMALL(RECHNEN!$C$1:$C$16,3),"3",IF(ABS(K14-21)=SMALL(RECHNEN!$C$1:$C$16,4),"4",IF(ABS(K14-21)=SMALL(RECHNEN!$C$1:$C$16,5),"5",IF(ABS(K14-21)=SMALL(RECHNEN!$C$1:$C$16,6),"6",IF(ABS(K14-21)=SMALL(RECHNEN!$C$1:$C$16,7),"7",IF(ABS(K14-21)=SMALL(RECHNEN!$C$1:$C$16,8),"8",IF(ABS(K14-21)=SMALL(RECHNEN!$C$1:$C$16,9),"9",IF(ABS(K14-21)=SMALL(RECHNEN!$C$1:$C$16,10),"10",IF(ABS(K14-21)=SMALL(RECHNEN!$C$1:$C$16,11),"11",IF(ABS(K14-21)=SMALL(RECHNEN!$C$1:$C$16,12),"12","13")))))))))))))))
I15: =SUM(B15,C15,D15,E15,F15,G15,H15) -> 0 | K15: =SUM(I15,J15) -> 0 | L15: =IF(AND(K15=0,J15=0),"",IF(K15>21,"TOT",IF(K15=21,"1",IF(ABS(K15-21)=SMALL(RECHNEN!$C$1:$C$16,1),"1",IF(ABS(K15-21)=SMALL(RECHNEN!$C$1:$C$16,2),"2",IF(ABS(K15-21)=SMALL(RECHNEN!$C$1:$C$16,3),"3",IF(ABS(K15-21)=SMALL(RECHNEN!$C$1:$C$16,4),"4",IF(ABS(K15-21)=SMALL(RECHNEN!$C$1:$C$16,5),"5",IF(ABS(K15-21)=SMALL(RECHNEN!$C$1:$C$16,6),"6",IF(ABS(K15-21)=SMALL(RECHNEN!$C$1:$C$16,7),"7",IF(ABS(K15-21)=SMALL(RECHNEN!$C$1:$C$16,8),"8",IF(ABS(K15-21)=SMALL(RECHNEN!$C$1:$C$16,9),"9",IF(ABS(K15-21)=SMALL(RECHNEN!$C$1:$C$16,10),"10",IF(ABS(K15-21)=SMALL(RECHNEN!$C$1:$C$16,11),"11",IF(ABS(K15-21)=SMALL(RECHNEN!$C$1:$C$16,12),"12","13")))))))))))))))
I16: =SUM(B16,C16,D16,E16,F16,G16,H16) -> 0 | K16: =SUM(I16,J16) -> 0 | L16: =IF(AND(K16=0,J16=0),"",IF(K16>21,"TOT",IF(K16=21,"1",IF(ABS(K16-21)=SMALL(RECHNEN!$C$1:$C$16,1),"1",IF(ABS(K16-21)=SMALL(RECHNEN!$C$1:$C$16,2),"2",IF(ABS(K16-21)=SMALL(RECHNEN!$C$1:$C$16,3),"3",IF(ABS(K16-21)=SMALL(RECHNEN!$C$1:$C$16,4),"4",IF(ABS(K16-21)=SMALL(RECHNEN!$C$1:$C$16,5),"5",IF(ABS(K16-21)=SMALL(RECHNEN!$C$1:$C$16,6),"6",IF(ABS(K16-21)=SMALL(RECHNEN!$C$1:$C$16,7),"7",IF(ABS(K16-21)=SMALL(RECHNEN!$C$1:$C$16,8),"8",IF(ABS(K16-21)=SMALL(RECHNEN!$C$1:$C$16,9),"9",IF(ABS(K16-21)=SMALL(RECHNEN!$C$1:$C$16,10),"10",IF(ABS(K16-21)=SMALL(RECHNEN!$C$1:$C$16,11),"11",IF(ABS(K16-21)=SMALL(RECHNEN!$C$1:$C$16,12),"12","13")))))))))))))))
I17: =SUM(B17,C17,D17,E17,F17,G17,H17) -> 0 | K17: =SUM(I17,J17) -> 0 | L17: =IF(AND(K17=0,J17=0),"",IF(K17>21,"TOT",IF(K17=21,"1",IF(ABS(K17-21)=SMALL(RECHNEN!$C$1:$C$16,1),"1",IF(ABS(K17-21)=SMALL(RECHNEN!$C$1:$C$16,2),"2",IF(ABS(K17-21)=SMALL(RECHNEN!$C$1:$C$16,3),"3",IF(ABS(K17-21)=SMALL(RECHNEN!$C$1:$C$16,4),"4",IF(ABS(K17-21)=SMALL(RECHNEN!$C$1:$C$16,5),"5",IF(ABS(K17-21)=SMALL(RECHNEN!$C$1:$C$16,6),"6",IF(ABS(K17-21)=SMALL(RECHNEN!$C$1:$C$16,7),"7",IF(ABS(K17-21)=SMALL(RECHNEN!$C$1:$C$16,8),"8",IF(ABS(K17-21)=SMALL(RECHNEN!$C$1:$C$16,9),"9",IF(ABS(K17-21)=SMALL(RECHNEN!$C$1:$C$16,10),"10",IF(ABS(K17-21)=SMALL(RECHNEN!$C$1:$C$16,11),"11",IF(ABS(K17-21)=SMALL(RECHNEN!$C$1:$C$16,12),"12","13")))))))))))))))
I18: =SUM(B18,C18,D18,E18,F18,G18,H18) -> 0 | K18: =SUM(I18,J18) -> 0 | L18: =IF(AND(K18=0,J18=0),"",IF(K18>21,"TOT",IF(K18=21,"1",IF(ABS(K18-21)=SMALL(RECHNEN!$C$1:$C$16,1),"1",IF(ABS(K18-21)=SMALL(RECHNEN!$C$1:$C$16,2),"2",IF(ABS(K18-21)=SMALL(RECHNEN!$C$1:$C$16,3),"3",IF(ABS(K18-21)=SMALL(RECHNEN!$C$1:$C$16,4),"4",IF(ABS(K18-21)=SMALL(RECHNEN!$C$1:$C$16,5),"5",IF(ABS(K18-21)=SMALL(RECHNEN!$C$1:$C$16,6),"6",IF(ABS(K18-21)=SMALL(RECHNEN!$C$1:$C$16,7),"7",IF(ABS(K18-21)=SMALL(RECHNEN!$C$1:$C$16,8),"8",IF(ABS(K18-21)=SMALL(RECHNEN!$C$1:$C$16,9),"9",IF(ABS(K18-21)=SMALL(RECHNEN!$C$1:$C$16,10),"10",IF(ABS(K18-21)=SMALL(RECHNEN!$C$1:$C$16,11),"11",IF(ABS(K18-21)=SMALL(RECHNEN!$C$1:$C$16,12),"12","13")))))))))))))))

Sheet Fuchs
A1: Fuchsspiel
A2: Michael | B2: üû | N2: =SUM(D2:M2) -> 0 | O2: J N
A3: Hilde | B3: üû | N3: =SUM(D3:M3) -> 0 | O3: J N
A4: Peter | B4: üû | N4: =SUM(D4:M4) -> 0 | O4: J N
A5: Brigitte | B5: üû | N5: =SUM(D5:M5) -> 0 | O5: J N
A6: Elke | B6: üû | N6: =SUM(D6:M6) -> 0 | O6: J N
A7: Gerhard | B7: üû | N7: =SUM(D7:M7) -> 0 | O7: J N
A8: Helga | B8: üû | N8: =SUM(D8:M8) -> 0 | O8: J N
A9: Birgit | B9: üû | N9: =SUM(D9:M9) -> 0 | O9: J N
A10: Jo | B10: üû | N10: =SUM(D10:M10) -> 0 | O10: J N
A11: Svenja | B11: üû | N11: =SUM(D11:M11) -> 0
A12: Marius | B12: üû | N12: =SUM(D12:M12) -> 0
B13: üû | C13: Fuchs Name | N13: =SUM(D13:M13) -> 0
C15: Jäger alle | N15: =SUM(D15:M15) -> 0

Sheet 6 Tage Rennen
A1: 6 Tage Rennen
A2: Name | B2: 1 Tag | C2: 2 Tag | D2: 2 Tag x2 | E2: Zsumme | F2: 3 Tag | G2: 3 Tag x3 | H2: Zsumme | I2: 4 Tag | J2: 4 Tag x4 | K2: Zsumme | L2: 5 Tag | M2: 5 Tag x5 | N2: Zsumme | O2: 6 Tag | P2: 6 Tag x6 | Q2: Gsumme | R2: Platz
A3: Michael | D3: =C3*2 -> 0 | E3: =D3+B3 -> 0 | G3: =F3*3 -> 0 | H3: =G3+E3 -> 0 | J3: =I3*4 -> 0 | K3: =J3+H3 -> 0 | M3: =L3*5 -> 0 | N3: =M3+K3 -> 0 | P3: =O3*6 -> 0 | Q3: =P3+N3 -> 0 | R3: =IF(Q3=0,"",IF(Q3=LARGE($Q$3:$Q$16,1),"1",IF(Q3=LARGE($Q$3:$Q$16,2),"2",IF(Q3=LARGE($Q$3:$Q$16,3),"3",IF(Q3=LARGE($Q$3:$Q$16,4),"4",IF(Q3=LARGE($Q$3:$Q$16,5),"5",IF(Q3=LARGE($Q$3:$Q$16,6),"6","7")))))))
A4: Hilde | D4: =C4*2 -> 0 | E4: =D4+B4 -> 0 | G4: =F4*3 -> 0 | H4: =G4+E4 -> 0 | J4: =I4*4 -> 0 | K4: =J4+H4 -> 0 | M4: =L4*5 -> 0 | N4: =M4+K4 -> 0 | P4: =O4*6 -> 0 | Q4: =P4+N4 -> 0 | R4: =R3
A5: Peter | D5: =C5*2 -> 0 | E5: =D5+B5 -> 0 | G5: =F5*3 -> 0 | H5: =G5+E5 -> 0 | J5: =I5*4 -> 0 | K5: =J5+H5 -> 0 | M5: =L5*5 -> 0 | N5: =M5+K5 -> 0 | P5: =O5*6 -> 0 | Q5: =P5+N5 -> 0 | R5: =IF(Q5=0,"",IF(Q5=LARGE($Q$3:$Q$16,1),"1",IF(Q5=LARGE($Q$3:$Q$16,2),"2",IF(Q5=LARGE($Q$3:$Q$16,3),"3",IF(Q5=LARGE($Q$3:$Q$16,4),"4",IF(Q5=LARGE($Q$3:$Q$16,5),"5",IF(Q5=LARGE($Q$3:$Q$16,6),"6","7")))))))
A6: Brigitte | D6: =C6*2 -> 0 | E6: =D6+B6 -> 0 | G6: =F6*3 -> 0 | H6: =G6+E6 -> 0 | J6: =I6*4 -> 0 | K6: =J6+H6 -> 0 | M6: =L6*5 -> 0 | N6: =M6+K6 -> 0 | P6: =O6*6 -> 0 | Q6: =P6+N6 -> 0 | R6: =R5
A7: Elke | D7: =C7*2 -> 0 | E7: =D7+B7 -> 0 | G7: =F7*3 -> 0 | H7: =G7+E7 -> 0 | J7: =I7*4 -> 0 | K7: =J7+H7 -> 0 | M7: =L7*5 -> 0 | N7: =M7+K7 -> 0 | P7: =O7*6 -> 0 | Q7: =P7+N7 -> 0 | R7: =IF(Q7=0,"",IF(Q7=LARGE($Q$3:$Q$16,1),"1",IF(Q7=LARGE($Q$3:$Q$16,2),"2",IF(Q7=LARGE($Q$3:$Q$16,3),"3",IF(Q7=LARGE($Q$3:$Q$16,4),"4",IF(Q7=LARGE($Q$3:$Q$16,5),"5",IF(Q7=LARGE($Q$3:$Q$16,6),"6","7")))))))
A8: Gerhard | D8: =C8*2 -> 0 | E8: =D8+B8 -> 0 | G8: =F8*3 -> 0 | H8: =G8+E8 -> 0 | J8: =I8*4 -> 0 | K8: =J8+H8 -> 0 | M8: =L8*5 -> 0 | N8: =M8+K8 -> 0 | P8: =O8*6 -> 0 | Q8: =P8+N8 -> 0 | R8: =R7
A9: Helga | D9: =C9*2 -> 0 | E9: =D9+B9 -> 0 | G9: =F9*3 -> 0 | H9: =G9+E9 -> 0 | J9: =I9*4 -> 0 | K9: =J9+H9 -> 0 | M9: =L9*5 -> 0 | N9: =M9+K9 -> 0 | P9: =O9*6 -> 0 | Q9: =P9+N9 -> 0 | R9: =IF(Q9=0,"",IF(Q9=LARGE($Q$3:$Q$16,1),"1",IF(Q9=LARGE($Q$3:$Q$16,2),"2",IF(Q9=LARGE($Q$3:$Q$16,3),"3",IF(Q9=LARGE($Q$3:$Q$16,4),"4",IF(Q9=LARGE($Q$3:$Q$16,5),"5",IF(Q9=LARGE($Q$3:$Q$16,6),"6","7")))))))
A10: Birgit | D10: =C10*2 -> 0 | E10: =D10+B10 -> 0 | G10: =F10*3 -> 0 | H10: =G10+E10 -> 0 | J10: =I10*4 -> 0 | K10: =J10+H10 -> 0 | M10: =L10*5 -> 0 | N10: =M10+K10 -> 0 | P10: =O10*6 -> 0 | Q10: =P10+N10 -> 0 | R10: =R9
A11: Jo | R11: =IF(Q11=0,"",IF(Q11=LARGE($Q$3:$Q$16,1),"1",IF(Q11=LARGE($Q$3:$Q$16,2),"2",IF(Q11=LARGE($Q$3:$Q$16,3),"3",IF(Q11=LARGE($Q$3:$Q$16,4),"4",IF(Q11=LARGE($Q$3:$Q$16,5),"5",IF(Q11=LARGE($Q$3:$Q$16,6),"6","7")))))))
A12: Svenja | R12: =R11
A13: Marius | R13: =IF(Q13=0,"",IF(Q13=LARGE($Q$3:$Q$16,1),"1",IF(Q13=LARGE($Q$3:$Q$16,2),"2",IF(Q13=LARGE($Q$3:$Q$16,3),"3",IF(Q13=LARGE($Q$3:$Q$16,4),"4",IF(Q13=LARGE($Q$3:$Q$16,5),"5",IF(Q13=LARGE($Q$3:$Q$16,6),"6","7")))))))
R14: =R13
R15: =IF(Q15=0,"",IF(Q15=LARGE($Q$3:$Q$16,1),"1",IF(Q15=LARGE($Q$3:$Q$16,2),"2",IF(Q15=LARGE($Q$3:$Q$16,3),"3",IF(Q15=LARGE($Q$3:$Q$16,4),"4",IF(Q15=LARGE($Q$3:$Q$16,5),"5",IF(Q15=LARGE($Q$3:$Q$16,6),"6","7")))))))
R16: =IF(Q16=0,"",IF(Q16=LARGE($Q$3:$Q$16,1),"1",IF(Q16=LARGE($Q$3:$Q$16,2),"2",IF(Q16=LARGE($Q$3:$Q$16,3),"3",IF(Q16=LARGE($Q$3:$Q$16,4),"4",IF(Q16=LARGE($Q$3:$Q$16,5),"5",IF(Q16=LARGE($Q$3:$Q$16,6),"6","7")))))))

Sheet Einsacken
A1: Einsacken
A2: Gruppe 1 | C2: Wurftopf | E2: Wurftopf | G2: Wurftopf | I2: Wurftopf | K2: Wurftopf | M2: Wurftopf | O2: Gesamttopf | P2: Gewonnen:
A3: Name | C3: =IF(OR(COUNTIF(B3:B8,"5"),COUNTIF(B3:B8,"P")),0,SUM(B3:B8)) -> 0 | E3: =IF(OR(COUNTIF(D3:D8,"5"),COUNTIF(D3:D8,"P")),0,SUM(D3:D8)) -> 0 | G3: =IF(OR(COUNTIF(F3:F8,"5"),COUNTIF(F3:F8,"P")),0,SUM(F3:F8)) -> 0 | I3: =IF(OR(COUNTIF(H3:H8,"5"),COUNTIF(H3:H8,"P")),0,SUM(H3:H8)) -> 0 | K3: =IF(OR(COUNTIF(J3:J8,"5"),COUNTIF(J3:J8,"P")),0,SUM(J3:J8)) -> 0 | M3: =IF(OR(COUNTIF(L3:L8,"5"),COUNTIF(L3:L8,"P")),0,SUM(L3:L8)) -> 0 | O3: =SUM(C3,E3,G3,I3,K3,M3) -> 0
A4: Name
A5: Name
A6: Name
A7: Name
A8: Name
A10: Gruppe 2 | C10: Wurftopf | E10: Wurftopf | G10: Wurftopf | I10: Wurftopf | K10: Wurftopf | M10: Wurftopf | O10: Gesamttopf | P10: Gewonnen:
A11: Name | C11: =IF(OR(COUNTIF(B11:B16,"5"),COUNTIF(B11:B16,"P")),0,SUM(B11:B16)) -> 0 | E11: =IF(OR(COUNTIF(D11:D16,"5"),COUNTIF(D11:D16,"P")),0,SUM(D11:D16)) -> 0 | G11: =IF(OR(COUNTIF(F11:F16,"5"),COUNTIF(F11:F16,"P")),0,SUM(F11:F16)) -> 0 | I11: =IF(OR(COUNTIF(H11:H16,"5"),COUNTIF(H11:H16,"P")),0,SUM(H11:H16)) -> 0 | K11: =IF(OR(COUNTIF(J11:J16,"5"),COUNTIF(J11:J16,"P")),0,SUM(J11:J16)) -> 0 | M11: =IF(OR(COUNTIF(L11:L16,"5"),COUNTIF(L11:L16,"P")),0,SUM(L11:L16)) -> 0 | O11: =SUM(C11,E11,G11,I11,K11,M11) -> 0
A12: Name
A13: Name
A14: Name
A15: Name
A16: Name

Sheet Schweinepartie
A1: Schweinepartie/Zahlenlotto
A2: Name | B2: 0.2 | C2: 0.4 | D2: 0.6 | E2: 0.8 | F2: 1 | G2: Ergebnis | H2: Platz
G3: =SUM(B3,C3,D3,E3,F3) -> 0 | H3: =_xlfn.RANK.EQ(G3,$G$3:$G$16,0) -> 1
G4: =SUM(B4,C4,D4,E4,F4) -> 0 | H4: =_xlfn.RANK.EQ(G4,$G$3:$G$16,0) -> 1
G5: =SUM(B5,C5,D5,E5,F5) -> 0 | H5: =_xlfn.RANK.EQ(G5,$G$3:$G$16,0) -> 1
G6: =SUM(B6,C6,D6,E6,F6) -> 0 | H6: =_xlfn.RANK.EQ(G6,$G$3:$G$16,0) -> 1
G7: =SUM(B7,C7,D7,E7,F7) -> 0 | H7: =_xlfn.RANK.EQ(G7,$G$3:$G$16,0) -> 1
G8: =SUM(B8,C8,D8,E8,F8) -> 0 | H8: =_xlfn.RANK.EQ(G8,$G$3:$G$16,0) -> 1
G9: =SUM(B9,C9,D9,E9,F9) -> 0 | H9: =_xlfn.RANK.EQ(G9,$G$3:$G$16,0) -> 1
G10: =SUM(B10,C10,D10,E10,F10) -> 0 | H10: =_xlfn.RANK.EQ(G10,$G$3:$G$16,0) -> 1
G11: =SUM(B11,C11,D11,E11,F11) -> 0 | H11: =_xlfn.RANK.EQ(G11,$G$3:$G$16,0) -> 1
G12: =SUM(B12,C12,D12,E12,F12) -> 0 | H12: =_xlfn.RANK.EQ(G12,$G$3:$G$16,0) -> 1
G13: =SUM(B13,C13,D13,E13,F13) -> 0 | H13: =_xlfn.RANK.EQ(G13,$G$3:$G$16,0) -> 1
G14: =SUM(B14,C14,D14,E14,F14) -> 0 | H14: =_xlfn.RANK.EQ(G14,$G$3:$G$16,0) -> 1
... G16: =SUM(B16,C16,D16,E16,F16) -> 0 | H16: =_xlfn.RANK.EQ(G16,$G$3:$G$16,0) -> 1
A17: Wer Zahlt:
B28: =IF(AND(B14=SMALL(RECHNEN!K$36:K$49,1),NOT(EXACT(A14,B27)),NOT(EXACT(A14,B26))),$A14,IF(AND(B15=SMALL(RECHNEN!K$36:K$49,1),NOT(EXACT(A15,B27)),NOT(EXACT(A15,B26))),$A15,IF(AND(B16=SMALL(RECHNEN!K$36:K$49,1),NOT(EXACT(A16,B26)),NOT(EXACT(A16,B27))),$A16,IF(AND(B17=SMALL(RECHNEN!K$36:K$49,1),NOT(EXACT(A17,B26)),NOT(EXACT(A17,B27))),$A17,IF(AND(B18=SMALL(RECHNEN!K$36:K$49,1),NOT(EXACT(A18,B26)),NOT(EXACT(A18,B27))),$A18,IF(AND(B19=SMALL(RECHNEN!K46:K$49,1),NOT(EXACT(A19,B26)),NOT(EXACT(A19,B27))),$A19,IF(AND(B20=SMALL(RECHNEN!K$36:K$49,1),NOT(EXACT(A20,B26)),NOT(EXACT(A20,B27))),$A20,IF(AND(B21=SMALL(RECHNEN!K$36:K$49,1),NOT(EXACT(A21,B26)),NOT(EXACT(A21,B27))),$A21,IF(AND(B22=SMALL(RECHNEN!K$36:K$49,1),NOT(EXACT(A22,B26)),NOT(EXACT(A22,B27))),$A22,IF(AND(B23=SMALL(RECHNEN!K$36:K$49,1),NOT(EXACT(A23,B26)),NOT(EXACT(A23,B27))),$A23,IF(AND(B24=SMALL(RECHNEN!K$36:K$49,1),NOT(EXACT(A24,B26)),NOT(EXACT(A24,B27))),$A24,IF(AND(B25=SMALL(RECHNEN!K$36:K$49,1),NOT(EXACT(A25,B26)),NOT(EXACT(A25,B27))),$A25,""))))))))))))

Sheet Tannenbaum
A1: Tannenbaum | H1: Tannenbaum
A2: Gruppe 1 | G2: Gewonnen: | H2: Gruppe 2 | N2: Gewonnen:
B3: 1 | I3: 1
B4: 2 | C4: 2 | I4: 2 | J4: 2
B5: 3 | C5: 3 | D5: 3 | I5: 3 | J5: 3 | K5: 3
B6: 4 | C6: 4 | D6: 4 | E6: 4 | I6: 4 | J6: 4 | K6: 4 | L6: 4
B7: 5 | C7: 5 | D7: 5 | E7: 5 | F7: 5 | I7: 5 | J7: 5 | K7: 5 | L7: 5 | M7: 5
B8: 6 | C8: 6 | D8: 6 | E8: 6 | I8: 6 | J8: 6 | K8: 6 | L8: 6
B9: 7 | C9: 7 | D9: 7 | I9: 7 | J9: 7 | K9: 7
B10: 8 | C10: 8 | I10: 8 | J10: 8
B11: 9 | I11: 9

Sheet Idiotenkegeln
A1: Idiotenkegeln
A2: Name | B2: links | C2: rückw. d. d. Beine | D2: rechts | E2: Ergebnis | F2: Platzierung
A3: Michael | E3: =SUM(B3:D3) -> 0 | F3: =_xlfn.RANK.EQ(E3,$E$3:$E$17,0) -> 1
A4: Hilde | E4: =SUM(B4:D4) -> 0 | F4: =_xlfn.RANK.EQ(E4,$E$3:$E$17,0) -> 1
A5: Peter | E5: =SUM(B5:D5) -> 0 | F5: =_xlfn.RANK.EQ(E5,$E$3:$E$17,0) -> 1
A6: Brigitte | E6: =SUM(B6:D6) -> 0 | F6: =_xlfn.RANK.EQ(E6,$E$3:$E$17,0) -> 1
A7: Elke | E7: =SUM(B7:D7) -> 0 | F7: =_xlfn.RANK.EQ(E7,$E$3:$E$17,0) -> 1
A8: Gerhard | E8: =SUM(B8:D8) -> 0 | F8: =_xlfn.RANK.EQ(E8,$E$3:$E$17,0) -> 1
A9: Helga | E9: =SUM(B9:D9) -> 0 | F9: =_xlfn.RANK.EQ(E9,$E$3:$E$17,0) -> 1
A10: Birgit | E10: =SUM(B10:D10) -> 0 | F10: =_xlfn.RANK.EQ(E10,$E$3:$E$17,0) -> 1
A11: Jo | E11: =SUM(B11:D11) -> 0 | F11: =_xlfn.RANK.EQ(E11,$E$3:$E$17,0) -> 1
A12: Svenja | E12: =SUM(B12:D12) -> 0 | F12: =_xlfn.RANK.EQ(E12,$E$3:$E$17,0) -> 1
A13: Marius | E13: =SUM(B13:D13) -> 0 | F13: =_xlfn.RANK.EQ(E13,$E$3:$E$17,0) -> 1
E14: =SUM(B14:D14) -> 0 | F14: =_xlfn.RANK.EQ(E14,$E$3:$E$17,0) -> 1
E15: =SUM(B15:D15) -> 0 | F15: =_xlfn.RANK.EQ(E15,$E$3:$E$17,0) -> 1
E16: =SUM(B16:D16) -> 0 | F16: =_xlfn.RANK.EQ(E16,$E$3:$E$17,0) -> 1
E17: =SUM(B17:D17) -> 0 | F17: =_xlfn.RANK.EQ(E17,$E$3:$E$17,0) -> 1

Sheet Mensch-ärger-dich-nicht
A1: Mensch Ärger dich Nicht
A2: Name | B2: Gesamtsumme | C2: Platz | D2: Wurf 1 | E2: Wurf 2 | F2: Wurf 3 | G2: Wurf 4 | H2: Wurf 5 | I2: Wurf 6 | J2: Wurf 7 | K2: Wurf 8 | L2: Wurf 9 | M2: Wurf 10
A3: Michael | B3: =SUM(D3:X3) -> 0 | C3: =_xlfn.RANK.EQ(B3,$B$3:$B$14) -> 1
A4: Hilde | B4: =SUM(D4:X4) -> 0 | C4: =_xlfn.RANK.EQ(B4,$B$3:$B$14) -> 1
A5: Peter | B5: =SUM(D5:X5) -> 0 | C5: =_xlfn.RANK.EQ(B5,$B$3:$B$14) -> 1
A6: Brigitte | B6: =SUM(D6:X6) -> 0 | C6: =_xlfn.RANK.EQ(B6,$B$3:$B$14) -> 1
A7: Elke | B7: =SUM(D7:X7) -> 0 | C7: =_xlfn.RANK.EQ(B7,$B$3:$B$14) -> 1
A8: Gerhard | B8: =SUM(D8:X8) -> 0 | C8: =_xlfn.RANK.EQ(B8,$B$3:$B$14) -> 1
A9: Helga | B9: =SUM(D9:X9) -> 0 | C9: =_xlfn.RANK.EQ(B9,$B$3:$B$14) -> 1
A10: Birgit | B10: =SUM(D10:X10) -> 0 | C10: =_xlfn.RANK.EQ(B10,$B$3:$B$14) -> 1
A11: Jo | B11: =SUM(D11:X11) -> 0 | C11: =_xlfn.RANK.EQ(B11,$B$3:$B$14) -> 1
A12: Svenja | B12: =SUM(D12:X12) -> 0 | C12: =_xlfn.RANK.EQ(B12,$B$3:$B$14) -> 1
A13: Marius | B13: =SUM(D13:X13) -> 0 | C13: =_xlfn.RANK.EQ(B13,$B$3:$B$14) -> 1
B14: =SUM(D14:X14) -> 0 | C14: =_xlfn.RANK.EQ(B14,$B$3:$B$14) -> 1

Sheet Busfahren
A1: BUS | B1: Räder | H1: Mannschaft | J1: Name
A2: Bus 1
A3: Bus 2
A4: Bus 3
A5: Bus 4
A6: Bus 5
A7: Bus 6
A8: Bus 7
A9: Bus 8
A10: Bus 9

Sheet Kegelbuch
B1: Kegelbuch
A2: Name | B2: Startgeld | C2: Pudel | D2: Stina | E2: Schweinepartie | F2: Zu zahlen | G2: Punkte
A3: Michael | E3: =RECHNEN!O55 -> 0 | F3: =SUM(B3,C3/10,D3/10,E3) -> 0 | G3: =IF(ISERROR(VLOOKUP($A3,RECHNEN!$A$18:$I$33,9,0))=1,"",VLOOKUP($A3,RECHNEN!$A$18:$I$33,9,0)) -> 35
A4: Hilde | E4: =RECHNEN!O56 -> 0 | F4: =SUM(B4,C4/10,D4/10,E4) -> 0 | G4: =IF(ISERROR(VLOOKUP($A4,RECHNEN!$A$18:$I$33,9,0))=1,"",VLOOKUP($A4,RECHNEN!$A$18:$I$33,9,0)) -> 36
A5: Peter | E5: =RECHNEN!O57 -> 0 | F5: =SUM(B5,C5/10,D5/10,E5) -> 0 | G5: =IF(ISERROR(VLOOKUP($A5,RECHNEN!$A$18:$I$33,9,0))=1,"",VLOOKUP($A5,RECHNEN!$A$18:$I$33,9,0)) -> 36
A6: Brigitte | E6: =RECHNEN!O58 -> 0 | F6: =SUM(B6,C6/10,D6/10,E6) -> 0 | G6: =IF(ISERROR(VLOOKUP($A6,RECHNEN!$A$18:$I$33,9,0))=1,"",VLOOKUP($A6,RECHNEN!$A$18:$I$33,9,0)) -> 36
A7: Elke | E7: =RECHNEN!O59 -> 0 | F7: =SUM(B7,C7/10,D7/10,E7) -> 0 | G7: =IF(ISERROR(VLOOKUP($A7,RECHNEN!$A$18:$I$33,9,0))=1,"",VLOOKUP($A7,RECHNEN!$A$18:$I$33,9,0)) -> 36
A8: Gerhard | E8: =RECHNEN!O60 -> 0 | F8: =SUM(B8,C8/10,D8/10,E8) -> 0 | G8: =IF(ISERROR(VLOOKUP($A8,RECHNEN!$A$18:$I$33,9,0))=1,"",VLOOKUP($A8,RECHNEN!$A$18:$I$33,9,0)) -> 36
A9: Helga | E9: =RECHNEN!O61 -> 0 | F9: =SUM(B9,C9/10,D9/10,E9) -> 0 | G9: =IF(ISERROR(VLOOKUP($A9,RECHNEN!$A$18:$I$33,9,0))=1,"",VLOOKUP($A9,RECHNEN!$A$18:$I$33,9,0)) -> 36
A10: Birgit | E10: =RECHNEN!O62 -> 0 | F10: =SUM(B10,C10/10,D10/10,E10) -> 0 | G10: =IF(ISERROR(VLOOKUP($A10,RECHNEN!$A$18:$I$33,9,0))=1,"",VLOOKUP($A10,RECHNEN!$A$18:$I$33,9,0)) -> 36
A11: Jo | E11: =RECHNEN!O63 -> 0 | F11: =SUM(B11,C11/10,D11/10,E11) -> 0 | G11: =IF(ISERROR(VLOOKUP($A11,RECHNEN!$A$18:$I$33,9,0))=1,"",VLOOKUP($A11,RECHNEN!$A$18:$I$33,9,0)) -> 36
A12: Svenja | E12: =RECHNEN!O64 -> 0 | F12: =SUM(B12,C12/10,D12/10,E12) -> 0 | G12: =IF(ISERROR(VLOOKUP($A12,RECHNEN!$A$18:$I$33,9,0))=1,"",VLOOKUP($A12,RECHNEN!$A$18:$I$33,9,0)) -> 36
A13: Marius | E13: =RECHNEN!O65 -> 0 | F13: =SUM(B13,C13/10,D13/10,E13) -> 0 | G13: =IF(ISERROR(VLOOKUP($A13,RECHNEN!$A$18:$I$33,9,0))=1,"",VLOOKUP($A13,RECHNEN!$A$18:$I$33,9,0)) -> 36
E14: =RECHNEN!O66 -> 3 | F14: =SUM(B14,C14/10,D14/10,E14) -> 3 | G14: =IF(ISERROR(VLOOKUP($A14,RECHNEN!$A$18:$I$33,9,0))=1,"",VLOOKUP($A14,RECHNEN!$A$18:$I$33,9,0)) -> #N/A
E15: =RECHNEN!O67 -> 3 | F15: =SUM(B15,C15/10,D15/10,E15) -> 3 | G15: =IF(ISERROR(VLOOKUP($A15,RECHNEN!$A$18:$I$33,9,0))=1,"",VLOOKUP($A15,RECHNEN!$A$18:$I$33,9,0)) -> #N/A
B19: Gesamtsumme: | F19: =SUM(F3:F16) -> 6

Sheet RECHNEN
A1: =_xlfn.NUMBERVALUE(CONCATENATE(E1,F1,G1)) -> 0 | B1: =_xlfn.NUMBERVALUE(IF((CONCATENATE(I1,J1,K1))=0,999,(CONCATENATE(I1,J1,K1)))) -> 0 | C1: =IF('17 und 4'!K2>21,999,ABS('17 und 4'!K2-21)) -> 21 | E1: =IF('Große + Kleine Hausnummer'!B3="",0,('Große + Kleine Hausnummer'!B3)) -> 0 | F1: =IF('Große + Kleine Hausnummer'!C3="",0,('Große + Kleine Hausnummer'!C3)) -> 0 | G1: =IF('Große + Kleine Hausnummer'!D3="",0,('Große + Kleine Hausnummer'!D3)) -> 0 | I1: =IF('Große + Kleine Hausnummer'!F3="",0,('Große + Kleine Hausnummer'!F3)) -> 0 | J1: =IF('Große + Kleine Hausnummer'!G3="",0,('Große + Kleine Hausnummer'!G3)) -> 0 | K1: =IF('Große + Kleine Hausnummer'!H3="",0,('Große + Kleine Hausnummer'!H3)) -> 0 | Q1: =Kegelbuch!F3 -> 0 | R1: =Kegelbuch!#REF! -> #REF! | S1: =Kegelbuch!#REF! -> #REF! | T1: =Kegelbuch!#REF! -> #REF! | U1: =Kegelbuch!#REF! -> #REF! | V1: =Kegelbuch!#REF! -> #REF! | W1: =Kegelbuch!#REF! -> #REF! | X1: =Kegelbuch!#REF! -> #REF! | Y1: =Kegelbuch!#REF! -> #REF! | ... AB1: =Kegelbuch!#REF! -> #REF!
A2: =_xlfn.NUMBERVALUE(CONCATENATE(E2,F2,G2)) -> 0 | B2: =_xlfn.NUMBERVALUE(IF((CONCATENATE(I2,J2,K2))=0,999,(CONCATENATE(I2,J2,K2)))) -> 0 | C2: =IF('17 und 4'!K3>21,999,ABS('17 und 4'!K3-21)) -> 21 | E2: =IF('Große + Kleine Hausnummer'!B4="",0,('Große + Kleine Hausnummer'!B4)) -> 0 | F2: =IF('Große + Kleine Hausnummer'!C4="",0,('Große + Kleine Hausnummer'!C4)) -> 0 | G2: =IF('Große + Kleine Hausnummer'!D4="",0,('Große + Kleine Hausnummer'!D4)) -> 0 | I2: =IF('Große + Kleine Hausnummer'!F4="",0,('Große + Kleine Hausnummer'!F4)) -> 0 | J2: =IF('Große + Kleine Hausnummer'!G4="",0,('Große + Kleine Hausnummer'!G4)) -> 0 | K2: =IF('Große + Kleine Hausnummer'!H4="",0,('Große + Kleine Hausnummer'!H4)) -> 0 | Q2: =Kegelbuch!F4 -> 0 | R2: =Kegelbuch!#REF! -> #REF! | S2: =Kegelbuch!#REF! -> #REF! | T2: =Kegelbuch!#REF! -> #REF! | U2: =Kegelbuch!#REF! -> #REF! | V2: =Kegelbuch!#REF! -> #REF! | W2: =Kegelbuch!#REF! -> #REF! | X2: =Kegelbuch!#REF! -> #REF! | Y2: =Kegelbuch!#REF! -> #REF! | ... AB2: =Kegelbuch!#REF! -> #REF!
A3: =_xlfn.NUMBERVALUE(CONCATENATE(E3,F3,G3)) -> 0 | B3: =_xlfn.NUMBERVALUE(IF((CONCATENATE(I3,J3,K3))=0,999,(CONCATENATE(I3,J3,K3)))) -> 0 | C3: =IF('17 und 4'!K4>21,999,ABS('17 und 4'!K4-21)) -> 21 | E3: =IF('Große + Kleine Hausnummer'!B5="",0,('Große + Kleine Hausnummer'!B5)) -> 0 | F3: =IF('Große + Kleine Hausnummer'!C5="",0,('Große + Kleine Hausnummer'!C5)) -> 0 | G3: =IF('Große + Kleine Hausnummer'!D5="",0,('Große + Kleine Hausnummer'!D5)) -> 0 | I3: =IF('Große + Kleine Hausnummer'!F5="",0,('Große + Kleine Hausnummer'!F5)) -> 0 | J3: =IF('Große + Kleine Hausnummer'!G5="",0,('Große + Kleine Hausnummer'!G5)) -> 0 | K3: =IF('Große + Kleine Hausnummer'!H5="",0,('Große + Kleine Hausnummer'!H5)) -> 0 | Q3: =Kegelbuch!F5 -> 0 | R3: =Kegelbuch!#REF! -> #REF! | S3: =Kegelbuch!#REF! -> #REF! | T3: =Kegelbuch!#REF! -> #REF! | U3: =Kegelbuch!#REF! -> #REF! | V3: =Kegelbuch!#REF! -> #REF! | W3: =Kegelbuch!#REF! -> #REF! | X3: =Kegelbuch!#REF! -> #REF! | Y3: =Kegelbuch!#REF! -> #REF! | ... AB3: =Kegelbuch!#REF! -> #REF!
A4: =_xlfn.NUMBERVALUE(CONCATENATE(E4,F4,G4)) -> 0 | B4: =_xlfn.NUMBERVALUE(IF((CONCATENATE(I4,J4,K4))=0,999,(CONCATENATE(I4,J4,K4)))) -> 0 | C4: =IF('17 und 4'!K5>21,999,ABS('17 und 4'!K5-21)) -> 21 | E4: =IF('Große + Kleine Hausnummer'!B6="",0,('Große + Kleine Hausnummer'!B6)) -> 0 | F4: =IF('Große + Kleine Hausnummer'!C6="",0,('Große + Kleine Hausnummer'!C6)) -> 0 | G4: =IF('Große + Kleine Hausnummer'!D6="",0,('Große + Kleine Hausnummer'!D6)) -> 0 | I4: =IF('Große + Kleine Hausnummer'!F6="",0,('Große + Kleine Hausnummer'!F6)) -> 0 | J4: =IF('Große + Kleine Hausnummer'!G6="",0,('Große + Kleine Hausnummer'!G6)) -> 0 | K4: =IF('Große + Kleine Hausnummer'!H6="",0,('Große + Kleine Hausnummer'!H6)) -> 0 | Q4: =Kegelbuch!F6 -> 0 | R4: =Kegelbuch!#REF! -> #REF! | S4: =Kegelbuch!#REF! -> #REF! | T4: =Kegelbuch!#REF! -> #REF! | U4: =Kegelbuch!#REF! -> #REF! | V4: =Kegelbuch!#REF! -> #REF! | W4: =Kegelbuch!#REF! -> #REF! | X4: =Kegelbuch!#REF! -> #REF! | Y4: =Kegelbuch!#REF! -> #REF! | ... AB4: =Kegelbuch!#REF! -> #REF!
A5: =_xlfn.NUMBERVALUE(CONCATENATE(E5,F5,G5)) -> 0 | B5: =_xlfn.NUMBERVALUE(IF((CONCATENATE(I5,J5,K5))=0,999,(CONCATENATE(I5,J5,K5)))) -> 0 | C5: =IF('17 und 4'!K6>21,999,ABS('17 und 4'!K6-21)) -> 21 | E5: =IF('Große + Kleine Hausnummer'!B7="",0,('Große + Kleine Hausnummer'!B7)) -> 0 | F5: =IF('Große + Kleine Hausnummer'!C7="",0,('Große + Kleine Hausnummer'!C7)) -> 0 | G5: =IF('Große + Kleine Hausnummer'!D7="",0,('Große + Kleine Hausnummer'!D7)) -> 0 | I5: =IF('Große + Kleine Hausnummer'!F7="",0,('Große + Kleine Hausnummer'!F7)) -> 0 | J5: =IF('Große + Kleine Hausnummer'!G7="",0,('Große + Kleine Hausnummer'!G7)) -> 0 | K5: =IF('Große + Kleine Hausnummer'!H7="",0,('Große + Kleine Hausnummer'!H7)) -> 0 | Q5: =Kegelbuch!F7 -> 0 | R5: =Kegelbuch!#REF! -> #REF! | S5: =Kegelbuch!#REF! -> #REF! | T5: =Kegelbuch!#REF! -> #REF! | U5: =Kegelbuch!#REF! -> #REF! | V5: =Kegelbuch!#REF! -> #REF! | W5: =Kegelbuch!#REF! -> #REF! | X5: =Kegelbuch!#REF! -> #REF! | Y5: =Kegelbuch!#REF! -> #REF! | ... AB5: =Kegelbuch!#REF! -> #REF!
A6: =_xlfn.NUMBERVALUE(CONCATENATE(E6,F6,G6)) -> 0 | B6: =_xlfn.NUMBERVALUE(IF((CONCATENATE(I6,J6,K6))=0,999,(CONCATENATE(I6,J6,K6)))) -> 0 | C6: =IF('17 und 4'!K7>21,999,ABS('17 und 4'!K7-21)) -> 21 | E6: =IF('Große + Kleine Hausnummer'!B8="",0,('Große + Kleine Hausnummer'!B8)) -> 0 | F6: =IF('Große + Kleine Hausnummer'!C8="",0,('Große + Kleine Hausnummer'!C8)) -> 0 | G6: =IF('Große + Kleine Hausnummer'!D8="",0,('Große + Kleine Hausnummer'!D8)) -> 0 | I6: =IF('Große + Kleine Hausnummer'!F8="",0,('Große + Kleine Hausnummer'!F8)) -> 0 | J6: =IF('Große + Kleine Hausnummer'!G8="",0,('Große + Kleine Hausnummer'!G8)) -> 0 | K6: =IF('Große + Kleine Hausnummer'!H8="",0,('Große + Kleine Hausnummer'!H8)) -> 0 | Q6: =Kegelbuch!F8 -> 0 | R6: =Kegelbuch!#REF! -> #REF! | S6: =Kegelbuch!#REF! -> #REF! | T6: =Kegelbuch!#REF! -> #REF! | U6: =Kegelbuch!#REF! -> #REF! | V6: =Kegelbuch!#REF! -> #REF! | W6: =Kegelbuch!#REF! -> #REF! | X6: =Kegelbuch!#REF! -> #REF! | Y6: =Kegelbuch!#REF! -> #REF! | ... AB6: =Kegelbuch!#REF! -> #REF!
A7: =_xlfn.NUMBERVALUE(CONCATENATE(E7,F7,G7)) -> 0 | B7: =_xlfn.NUMBERVALUE(IF((CONCATENATE(I7,J7,K7))=0,999,(CONCATENATE(I7,J7,K7)))) -> 0 | C7: =IF('17 und 4'!K8>21,999,ABS('17 und 4'!K8-21)) -> 21 | E7: =IF('Große + Kleine Hausnummer'!B9="",0,('Große + Kleine Hausnummer'!B9)) -> 0 | F7: =IF('Große + Kleine Hausnummer'!C9="",0,('Große + Kleine Hausnummer'!C9)) -> 0 | G7: =IF('Große + Kleine Hausnummer'!D9="",0,('Große + Kleine Hausnummer'!D9)) -> 0 | I7: =IF('Große + Kleine Hausnummer'!F9="",0,('Große + Kleine Hausnummer'!F9)) -> 0 | J7: =IF('Große + Kleine Hausnummer'!G9="",0,('Große + Kleine Hausnummer'!G9)) -> 0 | K7: =IF('Große + Kleine Hausnummer'!H9="",0,('Große + Kleine Hausnummer'!H9)) -> 0 | Q7: =Kegelbuch!F9 -> 0 | R7: =Kegelbuch!#REF! -> #REF! | S7: =Kegelbuch!#REF! -> #REF! | T7: =Kegelbuch!#REF! -> #REF! | U7: =Kegelbuch!#REF! -> #REF! | V7: =Kegelbuch!#REF! -> #REF! | W7: =Kegelbuch!#REF! -> #REF! | X7: =Kegelbuch!#REF! -> #REF! | Y7: =Kegelbuch!#REF! -> #REF! | ... AB7: =Kegelbuch!#REF! -> #REF!
A8: =_xlfn.NUMBERVALUE(CONCATENATE(E8,F8,G8)) -> 0 | B8: =_xlfn.NUMBERVALUE(IF((CONCATENATE(I8,J8,K8))=0,999,(CONCATENATE(I8,J8,K8)))) -> 0 | C8: =IF('17 und 4'!K9>21,999,ABS('17 und 4'!K9-21)) -> 21 | E8: =IF('Große + Kleine Hausnummer'!B10="",0,('Große + Kleine Hausnummer'!B10)) -> 0 | F8: =IF('Große + Kleine Hausnummer'!C10="",0,('Große + Kleine Hausnummer'!C10)) -> 0 | G8: =IF('Große + Kleine Hausnummer'!D10="",0,('Große + Kleine Hausnummer'!D10)) -> 0 | I8: =IF('Große + Kleine Hausnummer'!F10="",0,('Große + Kleine Hausnummer'!F10)) -> 0 | J8: =IF('Große + Kleine Hausnummer'!G10="",0,('Große + Kleine Hausnummer'!G10)) -> 0 | K8: =IF('Große + Kleine Hausnummer'!H10="",0,('Große + Kleine Hausnummer'!H10)) -> 0 | Q8: =Kegelbuch!F10 -> 0 | R8: =Kegelbuch!#REF! -> #REF! | S8: =Kegelbuch!#REF! -> #REF! | T8: =Kegelbuch!#REF! -> #REF! | U8: =Kegelbuch!#REF! -> #REF! | V8: =Kegelbuch!#REF! -> #REF! | W8: =Kegelbuch!#REF! -> #REF! | X8: =Kegelbuch!#REF! -> #REF! | Y8: =Kegelbuch!#REF! -> #REF! | ... AB8: =Kegelbuch!#REF! -> #REF!
A9: =_xlfn.NUMBERVALUE(CONCATENATE(E9,F9,G9)) -> 0 | B9: =_xlfn.NUMBERVALUE(IF((CONCATENATE(I9,J9,K9))=0,999,(CONCATENATE(I9,J9,K9)))) -> 0 | C9: =IF('17 und 4'!K10>21,999,ABS('17 und 4'!K10-21)) -> 21 | E9: =IF('Große + Kleine Hausnummer'!B11="",0,('Große + Kleine Hausnummer'!B11)) -> 0 | F9: =IF('Große + Kleine Hausnummer'!C11="",0,('Große + Kleine Hausnummer'!C11)) -> 0 | G9: =IF('Große + Kleine Hausnummer'!D11="",0,('Große + Kleine Hausnummer'!D11)) -> 0 | I9: =IF('Große + Kleine Hausnummer'!F11="",0,('Große + Kleine Hausnummer'!F11)) -> 0 | J9: =IF('Große + Kleine Hausnummer'!G11="",0,('Große + Kleine Hausnummer'!G11)) -> 0 | K9: =IF('Große + Kleine Hausnummer'!H11="",0,('Große + Kleine Hausnummer'!H11)) -> 0 | Q9: =Kegelbuch!F11 -> 0 | R9: =Kegelbuch!#REF! -> #REF! | S9: =Kegelbuch!#REF! -> #REF! | T9: =Kegelbuch!#REF! -> #REF! | U9: =Kegelbuch!#REF! -> #REF! | V9: =Kegelbuch!#REF! -> #REF! | W9: =Kegelbuch!#REF! -> #REF! | X9: =Kegelbuch!#REF! -> #REF! | Y9: =Kegelbuch!#REF! -> #REF! | ... AB9: =Kegelbuch!#REF! -> #REF!
A10: =_xlfn.NUMBERVALUE(CONCATENATE(E10,F10,G10)) -> 0 | B10: =_xlfn.NUMBERVALUE(IF((CONCATENATE(I10,J10,K10))=0,999,(CONCATENATE(I10,J10,K10)))) -> 0 | C10: =IF('17 und 4'!K11>21,999,ABS('17 und 4'!K11-21)) -> 21 | E10: =IF('Große + Kleine Hausnummer'!B12="",0,('Große + Kleine Hausnummer'!B12)) -> 0 | F10: =IF('Große + Kleine Hausnummer'!C12="",0,('Große + Kleine Hausnummer'!C12)) -> 0 | G10: =IF('Große + Kleine Hausnummer'!D12="",0,('Große + Kleine Hausnummer'!D12)) -> 0 | I10: =IF('Große + Kleine Hausnummer'!F12="",0,('Große + Kleine Hausnummer'!F12)) -> 0 | J10: =IF('Große + Kleine Hausnummer'!G12="",0,('Große + Kleine Hausnummer'!G12)) -> 0 | K10: =IF('Große + Kleine Hausnummer'!H12="",0,('Große + Kleine Hausnummer'!H12)) -> 0 | O10: =TODAY() -> 46166 | Q10: =Kegelbuch!F12 -> 0 | R10: =Kegelbuch!#REF! -> #REF! | S10: =Kegelbuch!#REF! -> #REF! | T10: =Kegelbuch!#REF! -> #REF! | U10: =Kegelbuch!#REF! -> #REF! | V10: =Kegelbuch!#REF! -> #REF! | W10: =Kegelbuch!#REF! -> #REF! | X10: =Kegelbuch!#REF! -> #REF! | Y10: =Kegelbuch!#REF! -> #REF! | ... AB10: =Kegelbuch!#REF! -> #REF!
A11: =_xlfn.NUMBERVALUE(CONCATENATE(E11,F11,G11)) -> 0 | B11: =_xlfn.NUMBERVALUE(IF((CONCATENATE(I11,J11,K11))=0,999,(CONCATENATE(I11,J11,K11)))) -> 0 | C11: =IF('17 und 4'!K12>21,999,ABS('17 und 4'!K12-21)) -> 21 | E11: =IF('Große + Kleine Hausnummer'!B13="",0,('Große + Kleine Hausnummer'!B13)) -> 0 | F11: =IF('Große + Kleine Hausnummer'!C13="",0,('Große + Kleine Hausnummer'!C13)) -> 0 | G11: =IF('Große + Kleine Hausnummer'!D13="",0,('Große + Kleine Hausnummer'!D13)) -> 0 | I11: =IF('Große + Kleine Hausnummer'!F13="",0,('Große + Kleine Hausnummer'!F13)) -> 0 | J11: =IF('Große + Kleine Hausnummer'!G13="",0,('Große + Kleine Hausnummer'!G13)) -> 0 | K11: =IF('Große + Kleine Hausnummer'!H13="",0,('Große + Kleine Hausnummer'!H13)) -> 0 | Q11: =Kegelbuch!F13 -> 0 | R11: =Kegelbuch!#REF! -> #REF! | S11: =Kegelbuch!#REF! -> #REF! | T11: =Kegelbuch!#REF! -> #REF! | U11: =Kegelbuch!#REF! -> #REF! | V11: =Kegelbuch!#REF! -> #REF! | W11: =Kegelbuch!#REF! -> #REF! | X11: =Kegelbuch!#REF! -> #REF! | Y11: =Kegelbuch!#REF! -> #REF! | ... AB11: =Kegelbuch!#REF! -> #REF!
A12: =_xlfn.NUMBERVALUE(CONCATENATE(E12,F12,G12)) -> 0 | B12: =_xlfn.NUMBERVALUE(IF((CONCATENATE(I12,J12,K12))=0,999,(CONCATENATE(I12,J12,K12)))) -> 0 | C12: =IF('17 und 4'!K13>21,999,ABS('17 und 4'!K13-21)) -> 21 | E12: =IF('Große + Kleine Hausnummer'!B14="",0,('Große + Kleine Hausnummer'!B14)) -> 0 | F12: =IF('Große + Kleine Hausnummer'!C14="",0,('Große + Kleine Hausnummer'!C14)) -> 0 | G12: =IF('Große + Kleine Hausnummer'!D14="",0,('Große + Kleine Hausnummer'!D14)) -> 0 | I12: =IF('Große + Kleine Hausnummer'!F14="",0,('Große + Kleine Hausnummer'!F14)) -> 0 | J12: =IF('Große + Kleine Hausnummer'!G14="",0,('Große + Kleine Hausnummer'!G14)) -> 0 | K12: =IF('Große + Kleine Hausnummer'!H14="",0,('Große + Kleine Hausnummer'!H14)) -> 0 | Q12: =Kegelbuch!F14 -> 3 | R12: =Kegelbuch!#REF! -> #REF! | S12: =Kegelbuch!#REF! -> #REF! | T12: =Kegelbuch!#REF! -> #REF! | U12: =Kegelbuch!#REF! -> #REF! | V12: =Kegelbuch!#REF! -> #REF! | W12: =Kegelbuch!#REF! -> #REF! | X12: =Kegelbuch!#REF! -> #REF! | Y12: =Kegelbuch!#REF! -> #REF! | ... AB12: =Kegelbuch!#REF! -> #REF!
A13: =_xlfn.NUMBERVALUE(CONCATENATE(E13,F13,G13)) -> 0 | B13: =_xlfn.NUMBERVALUE(IF((CONCATENATE(I13,J13,K13))=0,999,(CONCATENATE(I13,J13,K13)))) -> 0 | C13: =IF('17 und 4'!K14>21,999,ABS('17 und 4'!K14-21)) -> 21 | E13: =IF('Große + Kleine Hausnummer'!B15="",0,('Große + Kleine Hausnummer'!B15)) -> 0 | F13: =IF('Große + Kleine Hausnummer'!C15="",0,('Große + Kleine Hausnummer'!C15)) -> 0 | G13: =IF('Große + Kleine Hausnummer'!D15="",0,('Große + Kleine Hausnummer'!D15)) -> 0 | I13: =IF('Große + Kleine Hausnummer'!F15="",0,('Große + Kleine Hausnummer'!F15)) -> 0 | J13: =IF('Große + Kleine Hausnummer'!G15="",0,('Große + Kleine Hausnummer'!G15)) -> 0 | K13: =IF('Große + Kleine Hausnummer'!H15="",0,('Große + Kleine Hausnummer'!H15)) -> 0 | Q13: =Kegelbuch!F15 -> 3 | R13: =Kegelbuch!#REF! -> #REF! | S13: =Kegelbuch!#REF! -> #REF! | T13: =Kegelbuch!#REF! -> #REF! | U13: =Kegelbuch!#REF! -> #REF! | V13: =Kegelbuch!#REF! -> #REF! | W13: =Kegelbuch!#REF! -> #REF! | X13: =Kegelbuch!#REF! -> #REF! | Y13: =Kegelbuch!#REF! -> #REF! | ... AB13: =Kegelbuch!#REF! -> #REF!
A14: =_xlfn.NUMBERVALUE(CONCATENATE(E14,F14,G14)) -> 0 | B14: =_xlfn.NUMBERVALUE(IF((CONCATENATE(I14,J14,K14))=0,999,(CONCATENATE(I14,J14,K14)))) -> 0 | C14: =IF('17 und 4'!K15>21,999,ABS('17 und 4'!K15-21)) -> 21 | E14: =IF('Große + Kleine Hausnummer'!B16="",0,('Große + Kleine Hausnummer'!B16)) -> 0 | F14: =IF('Große + Kleine Hausnummer'!C16="",0,('Große + Kleine Hausnummer'!C16)) -> 0 | G14: =IF('Große + Kleine Hausnummer'!D16="",0,('Große + Kleine Hausnummer'!D16)) -> 0 | I14: =IF('Große + Kleine Hausnummer'!F16="",0,('Große + Kleine Hausnummer'!F16)) -> 0 | J14: =IF('Große + Kleine Hausnummer'!G16="",0,('Große + Kleine Hausnummer'!G16)) -> 0 | K14: =IF('Große + Kleine Hausnummer'!H16="",0,('Große + Kleine Hausnummer'!H16)) -> 0 | Q14: =Kegelbuch!F16 -> 0 | R14: =Kegelbuch!#REF! -> #REF! | S14: =Kegelbuch!#REF! -> #REF! | T14: =Kegelbuch!#REF! -> #REF! | U14: =Kegelbuch!#REF! -> #REF! | V14: =Kegelbuch!#REF! -> #REF! | W14: =Kegelbuch!#REF! -> #REF! | X14: =Kegelbuch!#REF! -> #REF! | Y14: =Kegelbuch!#REF! -> #REF! | ... AB14: =Kegelbuch!#REF! -> #REF!
A15: =_xlfn.NUMBERVALUE(CONCATENATE(E15,F15,G15)) -> 0 | B15: =_xlfn.NUMBERVALUE(IF((CONCATENATE(I15,J15,K15))=0,999,(CONCATENATE(I15,J15,K15)))) -> 0 | C15: =IF('17 und 4'!K16>21,999,ABS('17 und 4'!K16-21)) -> 21 | E15: =IF('Große + Kleine Hausnummer'!B17="",0,('Große + Kleine Hausnummer'!B17)) -> 0 | F15: =IF('Große + Kleine Hausnummer'!C17="",0,('Große + Kleine Hausnummer'!C17)) -> 0 | G15: =IF('Große + Kleine Hausnummer'!D17="",0,('Große + Kleine Hausnummer'!D17)) -> 0 | I15: =IF('Große + Kleine Hausnummer'!F17="",0,('Große + Kleine Hausnummer'!F17)) -> 0 | J15: =IF('Große + Kleine Hausnummer'!G17="",0,('Große + Kleine Hausnummer'!G17)) -> 0 | K15: =IF('Große + Kleine Hausnummer'!H17="",0,('Große + Kleine Hausnummer'!H17)) -> 0 | Q15: =Kegelbuch!F17 -> 0 | R15: =Kegelbuch!#REF! -> #REF! | S15: =Kegelbuch!#REF! -> #REF! | T15: =Kegelbuch!#REF! -> #REF! | U15: =Kegelbuch!#REF! -> #REF! | V15: =Kegelbuch!#REF! -> #REF! | W15: =Kegelbuch!#REF! -> #REF! | X15: =Kegelbuch!#REF! -> #REF! | Y15: =Kegelbuch!#REF! -> #REF! | ... AB15: =Kegelbuch!#REF! -> #REF!
Q16: =Kegelbuch!F18 -> 0 | R16: =Kegelbuch!#REF! -> #REF! | S16: =Kegelbuch!#REF! -> #REF! | T16: =Kegelbuch!#REF! -> #REF! | U16: =Kegelbuch!#REF! -> #REF! | V16: =Kegelbuch!#REF! -> #REF! | W16: =Kegelbuch!#REF! -> #REF! | X16: =Kegelbuch!#REF! -> #REF! | Y16: =Kegelbuch!#REF! -> #REF! | ... AB16: =Kegelbuch!#REF! -> #REF!
B17: 17 und 4 | C17: GuK | D17: Fuchs | E17: 6T | F17: Einsacken | G17: Tannebaum | H17: Idikegeln | I17: Ergebnis | K17: Schweine | N17: M.ä.d.n. | O17: Busfahren | Q17: =Kegelbuch!F19 -> 6 | R17: =Kegelbuch!#REF! -> #REF! | S17: =Kegelbuch!#REF! -> #REF! | T17: =Kegelbuch!#REF! -> #REF! | U17: =Kegelbuch!#REF! -> #REF! | V17: =Kegelbuch!#REF! -> #REF! | W17: =Kegelbuch!#REF! -> #REF! | X17: =Kegelbuch!#REF! -> #REF! | Y17: =Kegelbuch!#REF! -> #REF! | ... AB17: =Kegelbuch!#REF! -> #REF!
A18: Michael | B18: =IF(ISERROR($L$34+1-VLOOKUP($A18,'17 und 4'!$A$2:$L$18,12,0))=TRUE,0,$L$34+1-VLOOKUP($A18,'17 und 4'!$A$2:$L$18,12,0)) -> 0 | C18: =SUM(IF(ISERROR($L$34+1-VLOOKUP($A18,'Große + Kleine Hausnummer'!$A$3:$E$15,5,0))=TRUE,0,$L$34+1-VLOOKUP($A18,'Große + Kleine Hausnummer'!$A$3:$E$15,5,0)),IF(ISERROR($L$34+1-VLOOKUP($A18,'Große + Kleine Hausnummer'!$A$3:$I$15,9,0))=TRUE,0,$L$34+1-VLOOKUP($A18,'Große + Kleine Hausnummer'!$A$3:$I$15,9,0))) -> 12 | D18: =IF(ISERROR($L$34+1-D35)=TRUE,0,$L$34+1-D35) -> 1 | E18: =IF(ISERROR(32+1-VLOOKUP($A18,'6 Tage Rennen'!$A$3:$R$16,18,0))=TRUE,0,$L$34+2-2*VLOOKUP($A18,'6 Tage Rennen'!$A$3:$R$16,18,0)) -> 0 | F18: =IF(ISERROR($L$34+1-E35)=TRUE,0,$L$34+1-E35) -> 0 | G18: =IF(ISERROR($L$34+1-VLOOKUP($A18,$G$35:$I$52,3,0))=TRUE,0,$L$34+1-VLOOKUP($A18,$G$35:$I$52,3,0)) -> 0 | H18: =IF(ISERROR($L$34+1-VLOOKUP($A18,Idiotenkegeln!$A$3:$F$17,6,0))=TRUE,0,($L$34+1-VLOOKUP($A18,Idiotenkegeln!$A$3:$F$17,6,0))) -> 11 | I18: =SUM(B18:H18,K18,N18,O18) -> 35 | K18: =IF(ISERROR($L$34+1-VLOOKUP($A18,Schweinepartie!$A$3:$H$16,8,0))=TRUE,0,($L$34+1-VLOOKUP($A18,Schweinepartie!$A$3:$H$16,8,0))) -> 0 | L18: =IF('Große + Kleine Hausnummer'!A3="",0,1) -> 1 | N18: =IF(ISERROR($L$34+1-VLOOKUP($A18,'Mensch-ärger-dich-nicht'!$A$3:$L$19,3,0))=TRUE,0,$L$34+1-VLOOKUP($A18,'Mensch-ärger-dich-nicht'!$A$3:$L$19,3,0)) -> 11 | O18: =IFERROR(VLOOKUP(Q18,$R$19:$U$28,4),0) -> 0 | Q18: =IF(ISERROR(SEARCH(A18,Busfahren!$H$2)),IF(ISERROR(SEARCH(A18,Busfahren!$H$3)),IF(ISERROR(SEARCH(A18,Busfahren!$H$4)),IF(ISERROR(SEARCH(A18,Busfahren!$H$5)),IF(ISERROR(SEARCH(A18,Busfahren!$H$6)),IF(ISERROR(SEARCH(A18,Busfahren!$H$7)),IF(ISERROR(SEARCH(A18,Busfahren!$H$8)),IF(ISERROR(SEARCH(A18,Busfahren!$H$9)),IF(ISERROR(SEARCH(A18,Busfahren!$H$10)),"Bus 0","Bus 9"),"Bus 8"),"Bus 7"),"Bus 6"),"Bus 5"),"Bus 4"),"Bus 3"),"Bus 2"),"Bus 1") -> Bus 0 | R18: Busnamen | S18: Rang | U18: Punkte | W18: Anzahl Räder
A19: Hilde | B19: =IF(ISERROR($L$34+1-VLOOKUP($A19,'17 und 4'!$A$2:$L$18,12,0))=TRUE,0,$L$34+1-VLOOKUP($A19,'17 und 4'!$A$2:$L$18,12,0)) -> 0 | C19: =SUM(IF(ISERROR($L$34+1-VLOOKUP($A19,'Große + Kleine Hausnummer'!$A$3:$E$15,5,0))=TRUE,0,$L$34+1-VLOOKUP($A19,'Große + Kleine Hausnummer'!$A$3:$E$15,5,0)),IF(ISERROR($L$34+1-VLOOKUP($A19,'Große + Kleine Hausnummer'!$A$3:$I$15,9,0))=TRUE,0,$L$34+1-VLOOKUP($A19,'Große + Kleine Hausnummer'!$A$3:$I$15,9,0))) -> 12 | D19: =IF(ISERROR($L$34+1-D36)=TRUE,0,$L$34+1-D36) -> 1 | E19: =IF(ISERROR(32+1-VLOOKUP($A19,'6 Tage Rennen'!$A$3:$R$16,18,0))=TRUE,0,$L$34+2-2*VLOOKUP($A19,'6 Tage Rennen'!$A$3:$R$16,18,0)) -> 0 | F19: =IF(ISERROR($L$34+1-E36)=TRUE,0,$L$34+1-E36) -> 1 | G19: =IF(ISERROR($L$34+1-VLOOKUP($A19,$G$35:$I$52,3,0))=TRUE,0,$L$34+1-VLOOKUP($A19,$G$35:$I$52,3,0)) -> 0 | H19: =IF(ISERROR($L$34+1-VLOOKUP($A19,Idiotenkegeln!$A$3:$F$17,6,0))=TRUE,0,($L$34+1-VLOOKUP($A19,Idiotenkegeln!$A$3:$F$17,6,0))) -> 11 | I19: =SUM(B19:H19,K19,N19,O19) -> 36 | K19: =IF(ISERROR($L$34+1-VLOOKUP($A19,Schweinepartie!$A$3:$H$16,8,0))=TRUE,0,($L$34+1-VLOOKUP($A19,Schweinepartie!$A$3:$H$16,8,0))) -> 0 | L19: =IF('Große + Kleine Hausnummer'!A4="",0,1) -> 1 | N19: =IF(ISERROR($L$34+1-VLOOKUP($A19,'Mensch-ärger-dich-nicht'!$A$3:$L$19,3,0))=TRUE,0,$L$34+1-VLOOKUP($A19,'Mensch-ärger-dich-nicht'!$A$3:$L$19,3,0)) -> 11 | O19: =IFERROR(VLOOKUP(Q19,$R$19:$U$28,4),0) -> 0 | Q19: =IF(ISERROR(SEARCH(A19,Busfahren!$H$2)),IF(ISERROR(SEARCH(A19,Busfahren!$H$3)),IF(ISERROR(SEARCH(A19,Busfahren!$H$4)),IF(ISERROR(SEARCH(A19,Busfahren!$H$5)),IF(ISERROR(SEARCH(A19,Busfahren!$H$6)),IF(ISERROR(SEARCH(A19,Busfahren!$H$7)),IF(ISERROR(SEARCH(A19,Busfahren!$H$8)),IF(ISERROR(SEARCH(A19,Busfahren!$H$9)),IF(ISERROR(SEARCH(A19,Busfahren!$H$10)),"Bus 0","Bus 9"),"Bus 8"),"Bus 7"),"Bus 6"),"Bus 5"),"Bus 4"),"Bus 3"),"Bus 2"),"Bus 1") -> Bus 0 | R19: Bus 1 | S19: =_xlfn.RANK.EQ(W19,$W$19:$W$28,) -> 1 | T19: =IF(Busfahren!H2="",0,1) -> 0 | U19: =ROUNDUP($L$34-(S19-1)*$T$28,0) -> #DIV/0! | W19: =COUNTIF(Busfahren!B2:G2, "O") -> 0
A20: Peter | B20: =IF(ISERROR($L$34+1-VLOOKUP($A20,'17 und 4'!$A$2:$L$18,12,0))=TRUE,0,$L$34+1-VLOOKUP($A20,'17 und 4'!$A$2:$L$18,12,0)) -> 0 | C20: =SUM(IF(ISERROR($L$34+1-VLOOKUP($A20,'Große + Kleine Hausnummer'!$A$3:$E$15,5,0))=TRUE,0,$L$34+1-VLOOKUP($A20,'Große + Kleine Hausnummer'!$A$3:$E$15,5,0)),IF(ISERROR($L$34+1-VLOOKUP($A20,'Große + Kleine Hausnummer'!$A$3:$I$15,9,0))=TRUE,0,$L$34+1-VLOOKUP($A20,'Große + Kleine Hausnummer'!$A$3:$I$15,9,0))) -> 12 | D20: =IF(ISERROR($L$34+1-D37)=TRUE,0,$L$34+1-D37) -> 1 | E20: =IF(ISERROR(32+1-VLOOKUP($A20,'6 Tage Rennen'!$A$3:$R$16,18,0))=TRUE,0,$L$34+2-2*VLOOKUP($A20,'6 Tage Rennen'!$A$3:$R$16,18,0)) -> 0 | F20: =IF(ISERROR($L$34+1-E37)=TRUE,0,$L$34+1-E37) -> 1 | G20: =IF(ISERROR($L$34+1-VLOOKUP($A20,$G$35:$I$52,3,0))=TRUE,0,$L$34+1-VLOOKUP($A20,$G$35:$I$52,3,0)) -> 0 | H20: =IF(ISERROR($L$34+1-VLOOKUP($A20,Idiotenkegeln!$A$3:$F$17,6,0))=TRUE,0,($L$34+1-VLOOKUP($A20,Idiotenkegeln!$A$3:$F$17,6,0))) -> 11 | I20: =SUM(B20:H20,K20,N20,O20) -> 36 | K20: =IF(ISERROR($L$34+1-VLOOKUP($A20,Schweinepartie!$A$3:$H$16,8,0))=TRUE,0,($L$34+1-VLOOKUP($A20,Schweinepartie!$A$3:$H$16,8,0))) -> 0 | L20: =IF('Große + Kleine Hausnummer'!A5="",0,1) -> 1 | N20: =IF(ISERROR($L$34+1-VLOOKUP($A20,'Mensch-ärger-dich-nicht'!$A$3:$L$19,3,0))=TRUE,0,$L$34+1-VLOOKUP($A20,'Mensch-ärger-dich-nicht'!$A$3:$L$19,3,0)) -> 11 | O20: =IFERROR(VLOOKUP(Q20,$R$19:$U$28,4),0) -> 0 | Q20: =IF(ISERROR(SEARCH(A20,Busfahren!$H$2)),IF(ISERROR(SEARCH(A20,Busfahren!$H$3)),IF(ISERROR(SEARCH(A20,Busfahren!$H$4)),IF(ISERROR(SEARCH(A20,Busfahren!$H$5)),IF(ISERROR(SEARCH(A20,Busfahren!$H$6)),IF(ISERROR(SEARCH(A20,Busfahren!$H$7)),IF(ISERROR(SEARCH(A20,Busfahren!$H$8)),IF(ISERROR(SEARCH(A20,Busfahren!$H$9)),IF(ISERROR(SEARCH(A20,Busfahren!$H$10)),"Bus 0","Bus 9"),"Bus 8"),"Bus 7"),"Bus 6"),"Bus 5"),"Bus 4"),"Bus 3"),"Bus 2"),"Bus 1") -> Bus 0 | R20: Bus 2 | S20: =_xlfn.RANK.EQ(W20,$W$19:$W$28,) -> 1 | T20: =IF(Busfahren!H3="",0,1) -> 0 | U20: =ROUNDUP($L$34-(S20-1)*$T$28,0) -> #DIV/0! | W20: =COUNTIF(Busfahren!B3:G3, "O") -> 0
A21: Brigitte | B21: =IF(ISERROR($L$34+1-VLOOKUP($A21,'17 und 4'!$A$2:$L$18,12,0))=TRUE,0,$L$34+1-VLOOKUP($A21,'17 und 4'!$A$2:$L$18,12,0)) -> 0 | C21: =SUM(IF(ISERROR($L$34+1-VLOOKUP($A21,'Große + Kleine Hausnummer'!$A$3:$E$15,5,0))=TRUE,0,$L$34+1-VLOOKUP($A21,'Große + Kleine Hausnummer'!$A$3:$E$15,5,0)),IF(ISERROR($L$34+1-VLOOKUP($A21,'Große + Kleine Hausnummer'!$A$3:$I$15,9,0))=TRUE,0,$L$34+1-VLOOKUP($A21,'Große + Kleine Hausnummer'!$A$3:$I$15,9,0))) -> 12 | D21: =IF(ISERROR($L$34+1-D38)=TRUE,0,$L$34+1-D38) -> 1 | E21: =IF(ISERROR(32+1-VLOOKUP($A21,'6 Tage Rennen'!$A$3:$R$16,18,0))=TRUE,0,$L$34+2-2*VLOOKUP($A21,'6 Tage Rennen'!$A$3:$R$16,18,0)) -> 0 | F21: =IF(ISERROR($L$34+1-E38)=TRUE,0,$L$34+1-E38) -> 1 | G21: =IF(ISERROR($L$34+1-VLOOKUP($A21,$G$35:$I$52,3,0))=TRUE,0,$L$34+1-VLOOKUP($A21,$G$35:$I$52,3,0)) -> 0 | H21: =IF(ISERROR($L$34+1-VLOOKUP($A21,Idiotenkegeln!$A$3:$F$17,6,0))=TRUE,0,($L$34+1-VLOOKUP($A21,Idiotenkegeln!$A$3:$F$17,6,0))) -> 11 | I21: =SUM(B21:H21,K21,N21,O21) -> 36 | K21: =IF(ISERROR($L$34+1-VLOOKUP($A21,Schweinepartie!$A$3:$H$16,8,0))=TRUE,0,($L$34+1-VLOOKUP($A21,Schweinepartie!$A$3:$H$16,8,0))) -> 0 | L21: =IF('Große + Kleine Hausnummer'!A6="",0,1) -> 1 | N21: =IF(ISERROR($L$34+1-VLOOKUP($A21,'Mensch-ärger-dich-nicht'!$A$3:$L$19,3,0))=TRUE,0,$L$34+1-VLOOKUP($A21,'Mensch-ärger-dich-nicht'!$A$3:$L$19,3,0)) -> 11 | O21: =IFERROR(VLOOKUP(Q21,$R$19:$U$28,4),0) -> 0 | Q21: =IF(ISERROR(SEARCH(A21,Busfahren!$H$2)),IF(ISERROR(SEARCH(A21,Busfahren!$H$3)),IF(ISERROR(SEARCH(A21,Busfahren!$H$4)),IF(ISERROR(SEARCH(A21,Busfahren!$H$5)),IF(ISERROR(SEARCH(A21,Busfahren!$H$6)),IF(ISERROR(SEARCH(A21,Busfahren!$H$7)),IF(ISERROR(SEARCH(A21,Busfahren!$H$8)),IF(ISERROR(SEARCH(A21,Busfahren!$H$9)),IF(ISERROR(SEARCH(A21,Busfahren!$H$10)),"Bus 0","Bus 9"),"Bus 8"),"Bus 7"),"Bus 6"),"Bus 5"),"Bus 4"),"Bus 3"),"Bus 2"),"Bus 1") -> Bus 0 | R21: Bus 3 | S21: =_xlfn.RANK.EQ(W21,$W$19:$W$28,) -> 1 | T21: =IF(Busfahren!H4="",0,1) -> 0 | U21: =ROUNDUP($L$34-(S21-1)*$T$28,0) -> #DIV/0! | W21: =COUNTIF(Busfahren!B4:G4, "O") -> 0
A22: Elke | B22: =IF(ISERROR($L$34+1-VLOOKUP($A22,'17 und 4'!$A$2:$L$18,12,0))=TRUE,0,$L$34+1-VLOOKUP($A22,'17 und 4'!$A$2:$L$18,12,0)) -> 0 | C22: =SUM(IF(ISERROR($L$34+1-VLOOKUP($A22,'Große + Kleine Hausnummer'!$A$3:$E$15,5,0))=TRUE,0,$L$34+1-VLOOKUP($A22,'Große + Kleine Hausnummer'!$A$3:$E$15,5,0)),IF(ISERROR($L$34+1-VLOOKUP($A22,'Große + Kleine Hausnummer'!$A$3:$I$15,9,0))=TRUE,0,$L$34+1-VLOOKUP($A22,'Große + Kleine Hausnummer'!$A$3:$I$15,9,0))) -> 12 | D22: =IF(ISERROR($L$34+1-D39)=TRUE,0,$L$34+1-D39) -> 1 | E22: =IF(ISERROR(32+1-VLOOKUP($A22,'6 Tage Rennen'!$A$3:$R$16,18,0))=TRUE,0,$L$34+2-2*VLOOKUP($A22,'6 Tage Rennen'!$A$3:$R$16,18,0)) -> 0 | F22: =IF(ISERROR($L$34+1-E39)=TRUE,0,$L$34+1-E39) -> 1 | G22: =IF(ISERROR($L$34+1-VLOOKUP($A22,$G$35:$I$52,3,0))=TRUE,0,$L$34+1-VLOOKUP($A22,$G$35:$I$52,3,0)) -> 0 | H22: =IF(ISERROR($L$34+1-VLOOKUP($A22,Idiotenkegeln!$A$3:$F$17,6,0))=TRUE,0,($L$34+1-VLOOKUP($A22,Idiotenkegeln!$A$3:$F$17,6,0))) -> 11 | I22: =SUM(B22:H22,K22,N22,O22) -> 36 | K22: =IF(ISERROR($L$34+1-VLOOKUP($A22,Schweinepartie!$A$3:$H$16,8,0))=TRUE,0,($L$34+1-VLOOKUP($A22,Schweinepartie!$A$3:$H$16,8,0))) -> 0 | L22: =IF('Große + Kleine Hausnummer'!A7="",0,1) -> 1 | N22: =IF(ISERROR($L$34+1-VLOOKUP($A22,'Mensch-ärger-dich-nicht'!$A$3:$L$19,3,0))=TRUE,0,$L$34+1-VLOOKUP($A22,'Mensch-ärger-dich-nicht'!$A$3:$L$19,3,0)) -> 11 | O22: =IFERROR(VLOOKUP(Q22,$R$19:$U$28,4),0) -> 0 | Q22: =IF(ISERROR(SEARCH(A22,Busfahren!$H$2)),IF(ISERROR(SEARCH(A22,Busfahren!$H$3)),IF(ISERROR(SEARCH(A22,Busfahren!$H$4)),IF(ISERROR(SEARCH(A22,Busfahren!$H$5)),IF(ISERROR(SEARCH(A22,Busfahren!$H$6)),IF(ISERROR(SEARCH(A22,Busfahren!$H$7)),IF(ISERROR(SEARCH(A22,Busfahren!$H$8)),IF(ISERROR(SEARCH(A22,Busfahren!$H$9)),IF(ISERROR(SEARCH(A22,Busfahren!$H$10)),"Bus 0","Bus 9"),"Bus 8"),"Bus 7"),"Bus 6"),"Bus 5"),"Bus 4"),"Bus 3"),"Bus 2"),"Bus 1") -> Bus 0 | R22: Bus 4 | S22: =_xlfn.RANK.EQ(W22,$W$19:$W$28,) -> 1 | T22: =IF(Busfahren!H5="",0,1) -> 0 | U22: =ROUNDUP($L$34-(S22-1)*$T$28,0) -> #DIV/0! | W22: =COUNTIF(Busfahren!B5:G5, "O") -> 0
A23: Gerhard | B23: =IF(ISERROR($L$34+1-VLOOKUP($A23,'17 und 4'!$A$2:$L$18,12,0))=TRUE,0,$L$34+1-VLOOKUP($A23,'17 und 4'!$A$2:$L$18,12,0)) -> 0 | C23: =SUM(IF(ISERROR($L$34+1-VLOOKUP($A23,'Große + Kleine Hausnummer'!$A$3:$E$15,5,0))=TRUE,0,$L$34+1-VLOOKUP($A23,'Große + Kleine Hausnummer'!$A$3:$E$15,5,0)),IF(ISERROR($L$34+1-VLOOKUP($A23,'Große + Kleine Hausnummer'!$A$3:$I$15,9,0))=TRUE,0,$L$34+1-VLOOKUP($A23,'Große + Kleine Hausnummer'!$A$3:$I$15,9,0))) -> 12 | D23: =IF(ISERROR($L$34+1-D40)=TRUE,0,$L$34+1-D40) -> 1 | E23: =IF(ISERROR(32+1-VLOOKUP($A23,'6 Tage Rennen'!$A$3:$R$16,18,0))=TRUE,0,$L$34+2-2*VLOOKUP($A23,'6 Tage Rennen'!$A$3:$R$16,18,0)) -> 0 | F23: =IF(ISERROR($L$34+1-E40)=TRUE,0,$L$34+1-E40) -> 1 | G23: =IF(ISERROR($L$34+1-VLOOKUP($A23,$G$35:$I$52,3,0))=TRUE,0,$L$34+1-VLOOKUP($A23,$G$35:$I$52,3,0)) -> 0 | H23: =IF(ISERROR($L$34+1-VLOOKUP($A23,Idiotenkegeln!$A$3:$F$17,6,0))=TRUE,0,($L$34+1-VLOOKUP($A23,Idiotenkegeln!$A$3:$F$17,6,0))) -> 11 | I23: =SUM(B23:H23,K23,N23,O23) -> 36 | K23: =IF(ISERROR($L$34+1-VLOOKUP($A23,Schweinepartie!$A$3:$H$16,8,0))=TRUE,0,($L$34+1-VLOOKUP($A23,Schweinepartie!$A$3:$H$16,8,0))) -> 0 | L23: =IF('Große + Kleine Hausnummer'!A8="",0,1) -> 1 | N23: =IF(ISERROR($L$34+1-VLOOKUP($A23,'Mensch-ärger-dich-nicht'!$A$3:$L$19,3,0))=TRUE,0,$L$34+1-VLOOKUP($A23,'Mensch-ärger-dich-nicht'!$A$3:$L$19,3,0)) -> 11 | O23: =IFERROR(VLOOKUP(Q23,$R$19:$U$28,4),0) -> 0 | Q23: =IF(ISERROR(SEARCH(A23,Busfahren!$H$2)),IF(ISERROR(SEARCH(A23,Busfahren!$H$3)),IF(ISERROR(SEARCH(A23,Busfahren!$H$4)),IF(ISERROR(SEARCH(A23,Busfahren!$H$5)),IF(ISERROR(SEARCH(A23,Busfahren!$H$6)),IF(ISERROR(SEARCH(A23,Busfahren!$H$7)),IF(ISERROR(SEARCH(A23,Busfahren!$H$8)),IF(ISERROR(SEARCH(A23,Busfahren!$H$9)),IF(ISERROR(SEARCH(A23,Busfahren!$H$10)),"Bus 0","Bus 9"),"Bus 8"),"Bus 7"),"Bus 6"),"Bus 5"),"Bus 4"),"Bus 3"),"Bus 2"),"Bus 1") -> Bus 0 | R23: Bus 5 | S23: =_xlfn.RANK.EQ(W23,$W$19:$W$28,) -> 1 | T23: =IF(Busfahren!H6="",0,1) -> 0 | U23: =ROUNDUP($L$34-(S23-1)*$T$28,0) -> #DIV/0! | W23: =COUNTIF(Busfahren!B6:G6, "O") -> 0
A24: Helga | B24: =IF(ISERROR($L$34+1-VLOOKUP($A24,'17 und 4'!$A$2:$L$18,12,0))=TRUE,0,$L$34+1-VLOOKUP($A24,'17 und 4'!$A$2:$L$18,12,0)) -> 0 | C24: =SUM(IF(ISERROR($L$34+1-VLOOKUP($A24,'Große + Kleine Hausnummer'!$A$3:$E$15,5,0))=TRUE,0,$L$34+1-VLOOKUP($A24,'Große + Kleine Hausnummer'!$A$3:$E$15,5,0)),IF(ISERROR($L$34+1-VLOOKUP($A24,'Große + Kleine Hausnummer'!$A$3:$I$15,9,0))=TRUE,0,$L$34+1-VLOOKUP($A24,'Große + Kleine Hausnummer'!$A$3:$I$15,9,0))) -> 12 | D24: =IF(ISERROR($L$34+1-D41)=TRUE,0,$L$34+1-D41) -> 1 | E24: =IF(ISERROR(32+1-VLOOKUP($A24,'6 Tage Rennen'!$A$3:$R$16,18,0))=TRUE,0,$L$34+2-2*VLOOKUP($A24,'6 Tage Rennen'!$A$3:$R$16,18,0)) -> 0 | F24: =IF(ISERROR($L$34+1-E41)=TRUE,0,$L$34+1-E41) -> 1 | G24: =IF(ISERROR($L$34+1-VLOOKUP($A24,$G$35:$I$52,3,0))=TRUE,0,$L$34+1-VLOOKUP($A24,$G$35:$I$52,3,0)) -> 0 | H24: =IF(ISERROR($L$34+1-VLOOKUP($A24,Idiotenkegeln!$A$3:$F$17,6,0))=TRUE,0,($L$34+1-VLOOKUP($A24,Idiotenkegeln!$A$3:$F$17,6,0))) -> 11 | I24: =SUM(B24:H24,K24,N24,O24) -> 36 | K24: =IF(ISERROR($L$34+1-VLOOKUP($A24,Schweinepartie!$A$3:$H$16,8,0))=TRUE,0,($L$34+1-VLOOKUP($A24,Schweinepartie!$A$3:$H$16,8,0))) -> 0 | L24: =IF('Große + Kleine Hausnummer'!A9="",0,1) -> 1 | N24: =IF(ISERROR($L$34+1-VLOOKUP($A24,'Mensch-ärger-dich-nicht'!$A$3:$L$19,3,0))=TRUE,0,$L$34+1-VLOOKUP($A24,'Mensch-ärger-dich-nicht'!$A$3:$L$19,3,0)) -> 11 | O24: =IFERROR(VLOOKUP(Q24,$R$19:$U$28,4),0) -> 0 | Q24: =IF(ISERROR(SEARCH(A24,Busfahren!$H$2)),IF(ISERROR(SEARCH(A24,Busfahren!$H$3)),IF(ISERROR(SEARCH(A24,Busfahren!$H$4)),IF(ISERROR(SEARCH(A24,Busfahren!$H$5)),IF(ISERROR(SEARCH(A24,Busfahren!$H$6)),IF(ISERROR(SEARCH(A24,Busfahren!$H$7)),IF(ISERROR(SEARCH(A24,Busfahren!$H$8)),IF(ISERROR(SEARCH(A24,Busfahren!$H$9)),IF(ISERROR(SEARCH(A24,Busfahren!$H$10)),"Bus 0","Bus 9"),"Bus 8"),"Bus 7"),"Bus 6"),"Bus 5"),"Bus 4"),"Bus 3"),"Bus 2"),"Bus 1") -> Bus 0 | R24: Bus 6 | S24: =_xlfn.RANK.EQ(W24,$W$19:$W$28,) -> 1 | T24: =IF(Busfahren!H7="",0,1) -> 0 | U24: =ROUNDUP($L$34-(S24-1)*$T$28,0) -> #DIV/0! | W24: =COUNTIF(Busfahren!B7:G7, "O") -> 0
